Workbook

Sheet Summary 
B2: Over all summary -Mar-26
B3: Group | C3: A1 | D3: A2 | E3: A3 | F3: G1 | G3: G2 | H3: G3 | I3: G4 | J3: G5 | K3: G6 | L3: G7 | M3: G8 | N3: KMC | O3: PED | P3: PED-Auto | Q3: Total | Y3: Groupwise weekly summary
B4: Month Target | C4: 27096 | D4: 28980 | E4: 25836 | F4: 50232 | G4: 45460 | H4: 50232 | I4: 50232 | J4: 47972 | K4: 50232 | L4: 50232 | M4: 50232 | O4: 6900 | P4: 12190 | Q4: =SUM(C4:P4) -> 495826 | S4: No of days | BH4: Month target
B5: Day Target | C5: =C4/T6 -> 1204.2667 | D5: =D4/$T$6 -> 1288 | E5: =E4/$T$6 -> 1148.2667 | F5: =F4/$T$6 -> 2232.5333 | G5: =G4/$T$6 -> 2020.4444 | H5: =H4/$T$6 -> 2232.5333 | I5: =I4/$T$6 -> 2232.5333 | J5: =J4/$T$6 -> 2132.0889 | K5: =K4/$T$6 -> 2232.5333 | ... P5: =P4/$T$6 -> 541.77778 | Q5: =SUM(C5:P5) -> 22036.711 | Y5: Week 1 | BJ5: Group | BK5: A1 | BL5: A2 | BM5: A3 | BN5: G1 | BO5: G2 | BP5: G3 | BQ5: G4 | BR5: G5 | BS5: G6 | BT5: G7 | BU5: G8 | BV5: PED | BW5: No of days for week | BX5: Bal for month
B6: Opening WIP | C6: 3591 | D6: 4037.25 | E6: 2606.75 | F6: 3110.5 | G6: 4540.5 | H6: 2856.75 | I6: 3292.75 | J6: 3806.5 | K6: 3869.25 | L6: 4417.25 | M6: 4219.75 | N6: 4475 | O6: 4524.5 | P6: 2625.5 | Q6: =SUM(C6:P6) -> 51973.25 | S6: Total Days | T6: 22.5 | AP6: Week 1 | AS6: Week 2 | AV6: Week 3 | AY6: Week 4 | BJ6: Month target | BK6: =C4 -> 27096 | BL6: =D4 -> 28980 | BM6: =E4 -> 25836 | BN6: =F4 -> 50232 | BO6: =G4 -> 45460 | BP6: =H4 -> 50232 | BQ6: =I4 -> 50232 | BR6: =J4 -> 47972 | ... BU6: =M4 -> 50232 | BV6: =O4 -> 6900
B7: Fresh input | C7: =SUMIF('Input '!P2:AB2,'Summary '!C3,'Input '!P1:AB1) -> 22844 | D7: =SUMIF('Input '!Q2:AC2,'Summary '!D3,'Input '!Q1:AC1) -> 21993 | E7: =SUMIF('Input '!R2:AD2,'Summary '!E3,'Input '!R1:AD1) -> 21182 | F7: =SUMIF('Input '!S2:AE2,'Summary '!F3,'Input '!S1:AE1) -> 40287 | G7: =SUMIF('Input '!T2:AF2,'Summary '!G3,'Input '!T1:AF1) -> 39597 | H7: =SUMIF('Input '!U2:AG2,'Summary '!H3,'Input '!U1:AG1) -> 38817 | I7: =SUMIF('Input '!V2:AH2,'Summary '!I3,'Input '!V1:AH1) -> 43103 | J7: =SUMIF('Input '!W2:AI2,'Summary '!J3,'Input '!W1:AI1) -> 39778 | ... P7: =SUMIF('Input '!AC2:AO2,'Summary '!P3,'Input '!AC1:AO1) -> 0 | Q7: =SUM(C7:P7) -> 410983 | S7: Comp days | T7: 22.5 | Y7: Group | Z7: A1 | AA7: A2 | AB7: A3 | AC7: G1 | AD7: G2 | AE7: G3 | AF7: G4 | AG7: G5 | AH7: G6 | AI7: G7 | AJ7: G8 | AK7: PED | AO7: Group | AP7: Add on | AQ7: Regular | AR7: PED | AS7: Add on | AT7: Regular | AU7: PED | AV7: Add on | AW7: Regular | AX7: PED | AY7: Add on | AZ7: Regular | BA7: PED | BI7: Week 1 | BJ7: Target | BK7: =C5*$BW$7 -> 4817.0667 | BL7: =D5*$BW$7 -> 5152 | BM7: =E5*$BW$7 -> 4593.0667 | BN7: =F5*$BW$7 -> 8930.1333 | BO7: =G5*$BW$7 -> 8081.7778 | BP7: =H5*$BW$7 -> 8930.1333 | BQ7: =I5*$BW$7 -> 8930.1333 | BR7: =J5*$BW$7 -> 8528.3556 | ... BU7: =M5*$BW$7 -> 8930.1333 | BV7: =O5*$BW$7 -> 1226.6667 | BW7: 4 | BX7: 23
B8: Input Rate | C8: =C7/$T$7 -> 1015.2889 | D8: =D7/$T$7 -> 977.46667 | E8: =E7/$T$7 -> 941.42222 | F8: =F7/$T$7 -> 1790.5333 | G8: =G7/$T$7 -> 1759.8667 | H8: =H7/$T$7 -> 1725.2 | I8: =I7/$T$7 -> 1915.6889 | J8: =J7/$T$7 -> 1767.9111 | ... P8: =P7/$T$7 -> 0 | Q8: =SUM(C8:P8) -> 18265.911 | S8: Bal days | T8: =T6-T7 -> 0 | Y8: Target | Z8: =BK7 -> 4817.0667 | AA8: =BL7 -> 5152 | AB8: =BM7 -> 4593.0667 | AC8: =BN7 -> 8930.1333 | AD8: =BO7 -> 8081.7778 | AE8: =BP7 -> 8930.1333 | AF8: =BQ7 -> 8930.1333 | AG8: =BR7 -> 8528.3556 | ... AK8: =BV7 -> 1226.6667 | AO8: Target | AP8: =Z8+AA8+AB8 -> 14562.133 | AQ8: =AC8+AD8+AE8+AF8+AG8+AH8+AI8+AJ8 -> 70190.933 | AR8: =AK8 -> 1226.6667 | AS8: =SUM(Z25:AB25) -> 21841.263 | AT8: =SUM(AC25:AJ25) -> 103803.16 | AU8: =AK25 -> 1268.8421 | AV8: =SUM(#REF!) -> #REF! | AW8: =SUM(#REF!) -> #REF! | AX8: =#REF! -> #REF! | AY8: =SUM(#REF!) -> #REF! | AZ8: =SUM(#REF!) -> #REF! | BA8: =#REF! -> #REF! | BJ8: Actual | BK8: ='Output '!AA4 -> 4006 | BL8: ='Output '!AB4 -> 4368 | BM8: ='Output '!AC4 -> 4374 | BN8: ='Output '!AD4 -> 8782 | BO8: ='Output '!AE4 -> 6892 | BP8: ='Output '!AF4 -> 9686 | BQ8: ='Output '!AG4 -> 10177 | BR8: ='Output '!AH4 -> 7112 | ... BU8: ='Output '!AK4 -> 6694 | BV8: ='Output '!AM4 -> 2882
B9: Stripping Qty | C9: ='Returns '!C4 -> 146 | D9: ='Returns '!D4 -> 157 | E9: ='Returns '!E4 -> 52 | F9: ='Returns '!F4 -> 152 | G9: ='Returns '!G4 -> 38 | H9: ='Returns '!H4 -> 159 | I9: ='Returns '!I4 -> 150 | J9: ='Returns '!J4 -> 111 | ... N9: ='Returns '!N4 -> 114 | O9: ='Returns '!N4 -> 114 | P9: ='Returns '!P4 -> 0 | Q9: =SUM(C9:P9) -> 1757 | Y9: Opening Wip | Z9: ='WIP '!S21 -> 3.591 | AA9: ='WIP '!T21 -> 4.03725 | AB9: ='WIP '!U21 -> 2.60675 | AC9: ='WIP '!V21 -> 3.1105 | AD9: ='WIP '!W21 -> 4.5405 | AE9: ='WIP '!X21 -> 2.85675 | AF9: ='WIP '!Y21 -> 3.29275 | AG9: ='WIP '!Z21 -> 3.8065 | ... AK9: ='WIP '!AD21 -> 4.475 | AO9: Opening Wip | AP9: =Z9+AA9+AB9 -> 10.235 | AQ9: =AC9+AD9+AE9+AF9+AG9+AH9+AI9+AJ9 -> 30.11325 | AR9: =AK9 -> 4.475 | AS9: =SUM(Z26:AB26) -> 11.829714 | AT9: =SUM(AC26:AJ26) -> 31.491857 | AU9: =AK26 -> 1.72 | AV9: =SUM(#REF!) -> #REF! | AW9: =SUM(#REF!) -> #REF! | AX9: =#REF! -> #REF! | AY9: =SUM(#REF!) -> #REF! | AZ9: =SUM(#REF!) -> #REF! | BA9: =#REF! -> #REF! | BJ9: Balance | BK9: =BK7-BK8 -> 811.06667 | BL9: =BL7-BL8 -> 784 | BM9: =BM7-BM8 -> 219.06667 | BN9: =BN7-BN8 -> 148.13333 | BO9: =BO7-BO8 -> 1189.7778 | BP9: =BP7-BP8 -> -755.86667 | BQ9: =BQ7-BQ8 -> -1246.8667 | BR9: =BR7-BR8 -> 1416.3556 | ... BV9: =BV7-BV8 -> -1655.3333
B10: Stripping Rate | C10: =C9/$T$7 -> 6.4888889 | D10: =D9/$T$7 -> 6.9777778 | E10: =E9/$T$7 -> 2.3111111 | F10: =F9/$T$7 -> 6.7555556 | G10: =G9/$T$7 -> 1.6888889 | H10: =H9/$T$7 -> 7.0666667 | I10: =I9/$T$7 -> 6.6666667 | J10: =J9/$T$7 -> 4.9333333 | ... P10: =P9/$T$7 -> 0 | Q10: =SUM(C10:P10) -> 78.088889 | S10: For Simple | T10: =T8-1 -> -1 | Y10: Fresh input | Z10: ='Input '!AG3 -> 3998 | AA10: ='Input '!AH3 -> 4356 | AB10: ='Input '!AI3 -> 4102 | AC10: ='Input '!AJ3 -> 7308 | AD10: ='Input '!AK3 -> 7329 | AE10: ='Input '!AL3 -> 7300 | AF10: ='Input '!AM3 -> 7391 | AG10: ='Input '!AN3 -> 7179 | ... AJ10: ='Input '!AQ3 -> 8047 | AK10: ='Input '!AS3 -> 5414 | AO10: Fresh input | AP10: =Z10+AA10+AB10 -> 12456 | AQ10: =AC10+AD10+AE10+AF10+AG10+AH10+AI10+AJ10 -> 61475 | AR10: =AK10 -> 5414 | AS10: =SUM(Z27:AB27) -> 23685 | AT10: =SUM(AC27:AJ27) -> 120855 | AU10: =AK27 -> 2618 | AV10: =SUM(#REF!) -> #REF! | AW10: =SUM(#REF!) -> #REF! | AX10: =#REF! -> #REF! | AY10: =SUM(#REF!) -> #REF! | AZ10: =SUM(#REF!) -> #REF! | BA10: =#REF! -> #REF! | BJ10: Bal for month | BK10: =BK6-BK8 -> 23090 | BL10: =BL6-BL8 -> 24612 | BM10: =BM6-BM8 -> 21462 | BN10: =BN6-BN8 -> 41450 | BO10: =BO6-BO8 -> 38568 | BP10: =BP6-BP8 -> 40546 | BQ10: =BQ6-BQ8 -> 40055 | BR10: =BR6-BR8 -> 40860 | ... BV10: =BV6-BV8 -> 4018
B11: Return Qty | C11: ='Returns '!C41 -> 92 | D11: ='Returns '!D41 -> 54 | E11: ='Returns '!E41 -> 13 | F11: ='Returns '!F41 -> 70 | G11: ='Returns '!G41 -> 0 | H11: ='Returns '!H41 -> 0 | I11: ='Returns '!I41 -> 149 | J11: ='Returns '!J41 -> 35 | ... N11: ='Returns '!N41 -> 0 | O11: ='Returns '!P41 -> 0 | P11: ='Returns '!Q41 -> 0 | Q11: =SUM(C11:P11) -> 477 | S11: For Add on | T11: =T8-2 -> -2 | Y11: Returns | Z11: ='Returns '!T41 -> 92 | AA11: ='Returns '!U41 -> 54 | AB11: ='Returns '!V41 -> 13 | AC11: ='Returns '!W41 -> 70 | AD11: ='Returns '!X41 -> 0 | AE11: ='Returns '!Y41 -> 0 | AF11: ='Returns '!Z41 -> 149 | AG11: ='Returns '!AA41 -> 35 | ... AK11: ='Returns '!AE41 -> 0 | AO11: Returns | AP11: =Z11+AA11+AB11 -> 159 | AQ11: =AC11+AD11+AE11+AF11+AG11+AH11+AI11+AJ11 -> 318 | AR11: =AK11 -> 0 | AS11: =SUM(Z28:AB28) -> 0 | AT11: =SUM(AC28:AJ28) -> 0 | AU11: =AK28 -> 0 | AV11: =SUM(#REF!) -> #REF! | AW11: =SUM(#REF!) -> #REF! | AX11: =#REF! -> #REF! | AY11: =SUM(#REF!) -> #REF! | AZ11: =SUM(#REF!) -> #REF! | BA11: =#REF! -> #REF! | BJ11: Day rate Req | BK11: =BK10/$BX$12 -> 1215.2632 | BL11: =BL10/$BX$12 -> 1295.3684 | BM11: =BM10/$BX$12 -> 1129.5789 | BN11: =BN10/$BX$12 -> 2181.5789 | BO11: =BO10/$BX$12 -> 2029.8947 | BP11: =BP10/$BX$12 -> 2134 | BQ11: =BQ10/$BX$12 -> 2108.1579 | BR11: =BR10/$BX$12 -> 2150.5263 | ... BV11: =BV10/$BX$12 -> 211.47368
B12: Returns Rate | C12: =C11/$T$7 -> 4.0888889 | D12: =D11/$T$7 -> 2.4 | E12: =E11/$T$7 -> 0.57777778 | F12: =F11/$T$7 -> 3.1111111 | G12: =G11/$T$7 -> 0 | H12: =H11/$T$7 -> 0 | I12: =I11/$T$7 -> 6.6222222 | J12: =J11/$T$7 -> 1.5555556 | ... P12: =P11/$T$7 -> 0 | Q12: =SUM(C12:P12) -> 21.2 | Y12: Convertible WIP | Z12: =(Z9+Z10)-Z11 -> 3909.591 | AA12: =(AA9+AA10)-AA11 -> 4306.0373 | AB12: =(AB9+AB10)-AB11 -> 4091.6067 | AC12: =(AC9+AC10)-AC11 -> 7241.1105 | AD12: =(AD9+AD10)-AD11 -> 7333.5405 | AE12: =(AE9+AE10)-AE11 -> 7302.8567 | AF12: =(AF9+AF10)-AF11 -> 7245.2927 | AG12: =(AG9+AG10)-AG11 -> 7147.8065 | ... AK12: =(AK9+AK10)-AK11 -> 5418.475 | AO12: Con WIP | AP12: =Z12+AA12+AB12 -> 12307.235 | AQ12: =AC12+AD12+AE12+AF12+AG12+AH12+AI12+AJ12 -> 61187.113 | AR12: =AK12 -> 5418.475 | AS12: =SUM(Z29:AB29) -> 23696.83 | AT12: =SUM(AC29:AJ29) -> 120886.49 | AU12: =AK29 -> 2619.72 | AV12: =SUM(#REF!) -> #REF! | AW12: =SUM(#REF!) -> #REF! | AX12: =#REF! -> #REF! | AY12: =SUM(#REF!) -> #REF! | AZ12: =SUM(#REF!) -> #REF! | BA12: =#REF! -> #REF! | BI12: Week 2 | BJ12: Target | BK12: =BK11*$BW$12 -> 7291.5789 | BL12: =BL11*$BW$12 -> 7772.2105 | BM12: =BM11*$BW$12 -> 6777.4737 | BN12: =BN11*$BW$12 -> 13089.474 | BO12: =BO11*$BW$12 -> 12179.368 | BP12: =BP11*$BW$12 -> 12804 | BQ12: =BQ11*$BW$12 -> 12648.947 | BR12: =BR11*$BW$12 -> 12903.158 | ... BV12: =BV11*$BW$12 -> 1268.8421 | BW12: 6 | BX12: =BX7-BW7 -> 19
B13: Scrap Qty | C13: ='Returns '!C73 -> 13 | D13: ='Returns '!D73 -> 57 | E13: ='Returns '!E73 -> 12 | F13: ='Returns '!F73 -> 21 | G13: ='Returns '!G73 -> 5 | H13: ='Returns '!H73 -> 15 | I13: ='Returns '!I73 -> 87 | J13: ='Returns '!J73 -> 0 | ... N13: ='Returns '!N73 -> 5 | O13: ='Returns '!N73 -> 5 | P13: ='Returns '!P73 -> 0 | Q13: =SUM(C13:P13) -> 291 | Y13: Output | Z13: ='Output '!AA4 -> 4006 | AA13: ='Output '!AB4 -> 4368 | AB13: ='Output '!AC4 -> 4374 | AC13: ='Output '!AD4 -> 8782 | AD13: ='Output '!AE4 -> 6892 | AE13: ='Output '!AF4 -> 9686 | AF13: ='Output '!AG4 -> 10177 | AG13: ='Output '!AH4 -> 7112 | ... AJ13: ='Output '!AK4 -> 6694 | AK13: ='Output '!AM4 -> 2882 | AO13: Output | AP13: =Z13+AA13+AB13 -> 12748 | AQ13: =AC13+AD13+AE13+AF13+AG13+AH13+AI13+AJ13 -> 66114 | AR13: =AK13 -> 2882 | AS13: =SUM(Z30:AB30) -> 24111 | AT13: =SUM(AC30:AJ30) -> 120507 | AU13: =AK30 -> 5681 | AV13: =SUM(#REF!) -> #REF! | AW13: =SUM(#REF!) -> #REF! | AX13: =#REF! -> #REF! | AY13: =SUM(#REF!) -> #REF! | AZ13: =SUM(#REF!) -> #REF! | BA13: =#REF! -> #REF! | BJ13: Actual | BK13: ='Output '!AA5 -> 7784 | BL13: ='Output '!AB5 -> 8969 | BM13: ='Output '!AC5 -> 7358 | BN13: ='Output '!AD5 -> 15849 | BO13: ='Output '!AE5 -> 13473 | BP13: ='Output '!AF5 -> 15110 | BQ13: ='Output '!AG5 -> 16294 | BR13: ='Output '!AH5 -> 14293 | ... BU13: ='Output '!AK5 -> 14327 | BV13: ='Output '!AM5 -> 5681
B14: Scrap Rate | C14: =C13/$T$7 -> 0.57777778 | D14: =D13/$T$7 -> 2.5333333 | E14: =E13/$T$7 -> 0.53333333 | F14: =F13/$T$7 -> 0.93333333 | G14: =G13/$T$7 -> 0.22222222 | H14: =H13/$T$7 -> 0.66666667 | I14: =I13/$T$7 -> 3.8666667 | J14: =J13/$T$7 -> 0 | ... P14: =P13/$T$7 -> 0 | Q14: =SUM(C14:P14) -> 12.933333 | Y14: Balance | Z14: =Z8-Z13 -> 811.06667 | AA14: =AA8-AA13 -> 784 | AB14: =AB8-AB13 -> 219.06667 | AC14: =AC8-AC13 -> 148.13333 | AD14: =AD8-AD13 -> 1189.7778 | AE14: =AE8-AE13 -> -755.86667 | AF14: =AF8-AF13 -> -1246.8667 | AG14: =AG8-AG13 -> 1416.3556 | ... AK14: =AK8-AK13 -> -1655.3333 | AO14: Balance | AP14: =Z14+AA14+AB14 -> 1814.1333 | AQ14: =AC14+AD14+AE14+AF14+AG14+AH14+AI14+AJ14 -> 4076.9333 | AR14: =AK14 -> -1655.3333 | AS14: =SUM(Z31:AB31) -> -2269.7368 | AT14: =SUM(AC31:AJ31) -> -16703.842 | AU14: =AK31 -> -4412.1579 | AV14: =SUM(#REF!) -> #REF! | AW14: =SUM(#REF!) -> #REF! | AX14: =#REF! -> #REF! | AY14: =SUM(#REF!) -> #REF! | AZ14: =SUM(#REF!) -> #REF! | BA14: =#REF! -> #REF! | BJ14: Balance | BK14: =BK12-BK13 -> -492.42105 | BL14: =BL12-BL13 -> -1196.7895 | BM14: =BM12-BM13 -> -580.52632 | BN14: =BN12-BN13 -> -2759.5263 | BO14: =BO12-BO13 -> -1293.6316 | BP14: =BP12-BP13 -> -2306 | BQ14: =BQ12-BQ13 -> -3645.0526 | BR14: =BR12-BR13 -> -1389.8421 | ... BV14: =BV12-BV13 -> -4412.1579
B15: Bal input | C15: =MAX(C4-((C6+C7)-(C9+C11+C13)),0) -> 912 | D15: =MAX(D4-((D6+D7)-(D9+D11+D13)),0) -> 3217.75 | E15: =MAX(E4-((E6+E7)-(E9+E11+E13)),0) -> 2124.25 | F15: =MAX(F4-((F6+F7)-(F9+F11+F13)),0) -> 7077.5 | G15: =MAX(G4-((G6+G7)-(G9+G11+G13)),0) -> 1365.5 | H15: =MAX(H4-((H6+H7)-(H9+H11+H13)),0) -> 8732.25 | I15: =MAX(I4-((I6+I7)-(I9+I11+I13)),0) -> 4222.25 | J15: =MAX(J4-((J6+J7)-(J9+J11+J13)),0) -> 4533.5 | ... P15: =MAX(P4-((P6+P7)-(P9+P11+P13)),0) -> 9564.5 | Q15: =SUM(C15:P15) -> 61137.25 | Y15: Comp % | Z15: =Z13/Z8 -> 0.83162644 | AA15: =AA13/AA8 -> 0.84782609 | AB15: =AB13/AB8 -> 0.95230492 | AC15: =AC13/AC8 -> 0.98341197 | AD15: =AD13/AD8 -> 0.85278267 | AE15: =AE13/AE8 -> 1.0846423 | AF15: =AF13/AF8 -> 1.1396246 | AG15: =AG13/AG8 -> 0.83392396 | ... AK15: =AK13/AK8 -> 2.3494565 | AO15: Att % | BJ15: Bal for month | BK15: =BK6-(BK8+BK13) -> 15306 | BL15: =BL6-(BL8+BL13) -> 15643 | BM15: =BM6-(BM8+BM13) -> 14104 | BN15: =BN6-(BN8+BN13) -> 25601 | BO15: =BO6-(BO8+BO13) -> 25095 | BP15: =BP6-(BP8+BP13) -> 25436 | BQ15: =BQ6-(BQ8+BQ13) -> 23761 | BR15: =BR6-(BR8+BR13) -> 26567 | ... BV15: =BV6-(BV8+BV13) -> -1663
B16: Bal input Rate | C16: =C15/$T$10 -> -912 | D16: =D15/$T$10 -> -3217.75 | E16: =E15/$T$10 -> -2124.25 | F16: =F15/$T$10 -> -7077.5 | G16: =G15/$T$10 -> -1365.5 | H16: =H15/$T$10 -> -8732.25 | I16: =I15/$T$10 -> -4222.25 | J16: =J15/$T$10 -> -4533.5 | ... P16: =P15/$T$10 -> -9564.5 | Q16: =SUM(C16:P16) -> -61137.25 | Y16: Input Vs Output | Z16: =Z13/Z12 -> 1.0246596 | AA16: =AA13/AA12 -> 1.0143897 | AB16: =AB13/AB12 -> 1.0690177 | AC16: =AC13/AC12 -> 1.2127974 | AD16: =AD13/AD12 -> 0.93979163 | AE16: =AE13/AE12 -> 1.3263303 | AF16: =AF13/AF12 -> 1.4046361 | AG16: =AG13/AG12 -> 0.99499056 | ... AK16: =AK13/AK12 -> 0.53188397 | AO16: Comp % | AP16: =AP13/AP8 -> 0.87542118 | AQ16: =AQ13/AQ8 -> 0.94191652 | AR16: =AR13/AR8 -> 2.3494565 | AS16: =AS13/AS8 -> 1.1039197 | AT16: =AT13/AT8 -> 1.1609184 | AU16: =AU13/AU8 -> 4.4773104 | AV16: =AV13/AV8 -> #REF! | AW16: =AW13/AW8 -> #REF! | ... BA16: =BA13/BA8 -> #REF! | BJ16: Day rate Req | BK16: =BK15/$BX$16 -> 1177.3846 | BL16: =BL15/$BX$16 -> 1203.3077 | BM16: =BM15/$BX$16 -> 1084.9231 | BN16: =BN15/$BX$16 -> 1969.3077 | BO16: =BO15/$BX$16 -> 1930.3846 | BP16: =BP15/$BX$16 -> 1956.6154 | BQ16: =BQ15/$BX$16 -> 1827.7692 | BR16: =BR15/$BX$16 -> 2043.6154 | ... BV16: =BV15/$BX$16 -> -127.92308 | BW16: 7 | BX16: =BX7-(BW12+BW7) -> 13
B17: Total output | C17: =SUMIF('Output '!J3:V3,'Summary '!C3,'Output '!J2:V2) -> 27255 | D17: =SUMIF('Output '!K3:W3,'Summary '!D3,'Output '!K2:W2) -> 28888 | E17: =SUMIF('Output '!L3:X3,'Summary '!E3,'Output '!L2:X2) -> 26211 | F17: =SUMIF('Output '!M3:Y3,'Summary '!F3,'Output '!M2:Y2) -> 49551 | G17: =SUMIF('Output '!N3:Z3,'Summary '!G3,'Output '!N2:Z2) -> 45322 | H17: =SUMIF('Output '!O3:AA3,'Summary '!H3,'Output '!O2:AA2) -> 50100 | I17: =SUMIF('Output '!P3:AB3,'Summary '!I3,'Output '!P2:AB2) -> 50127 | J17: =SUMIF('Output '!Q3:AC3,'Summary '!J3,'Output '!Q2:AC2) -> 46686 | ... P17: =SUMIF('Output '!W3:AI3,'Summary '!P3,'Output '!W2:AI2) -> 0 | Q17: =SUM(C17:P17) -> 483594 | AO17: Output Vs Input | BI17: Week 3 | BJ17: Target | BK17: =BK16*$BW$16 -> 8241.6923 | BL17: =BL16*$BW$16 -> 8423.1538 | BM17: =BM16*$BW$16 -> 7594.4615 | BN17: =BN16*$BW$16 -> 13785.154 | BO17: =BO16*$BW$16 -> 13512.692 | BP17: =BP16*$BW$16 -> 13696.308 | BQ17: =BQ16*$BW$16 -> 12794.385 | BR17: =BR16*$BW$16 -> 14305.308 | ... BV17: =BV16*$BW$16 -> -895.46154
B18: Output Rate | C18: =C17/$T$7 -> 1211.3333 | D18: =D17/$T$7 -> 1283.9111 | E18: =E17/$T$7 -> 1164.9333 | F18: =F17/$T$7 -> 2202.2667 | G18: =G17/$T$7 -> 2014.3111 | H18: =H17/$T$7 -> 2226.6667 | I18: =I17/$T$7 -> 2227.8667 | J18: =J17/$T$7 -> 2074.9333 | ... P18: =P17/$T$7 -> 0 | Q18: =SUM(C18:P18) -> 21493.067 | BJ18: Actual | BK18: ='Output '!AA6 -> 5596 | BL18: ='Output '!AB6 -> 4994 | BM18: ='Output '!AC6 -> 4962 | BN18: ='Output '!AD6 -> 10529 | BO18: ='Output '!AE6 -> 14462 | BP18: ='Output '!AF6 -> 10822 | BQ18: ='Output '!AG6 -> 8868 | BR18: ='Output '!AH6 -> 12067 | ... BU18: ='Output '!AK6 -> 11482 | BV18: ='Output '!AM6 -> 1293
B19: Avg Wip | C19: =SUMIF('WIP '!$C$5:$N$5,'Summary '!C3,'WIP '!$C$4:$N$4) -> 3374.5217 | D19: =SUMIF('WIP '!$C$5:$N$5,'Summary '!D3,'WIP '!$C$4:$N$4) -> 3749.8261 | E19: =SUMIF('WIP '!$C$5:$N$5,'Summary '!E3,'WIP '!$C$4:$N$4) -> 3453.4348 | F19: =SUMIF('WIP '!$C$5:$N$5,'Summary '!F3,'WIP '!$C$4:$N$4) -> 2571.0435 | G19: =SUMIF('WIP '!$C$5:$N$5,'Summary '!G3,'WIP '!$C$4:$N$4) -> 3361.3043 | H19: =SUMIF('WIP '!$C$5:$N$5,'Summary '!H3,'WIP '!$C$4:$N$4) -> 2337.6957 | I19: =SUMIF('WIP '!$C$5:$N$5,'Summary '!I3,'WIP '!$C$4:$N$4) -> 3202.087 | J19: =SUMIF('WIP '!$C$5:$N$5,'Summary '!J3,'WIP '!$C$4:$N$4) -> 4046.1304 | ... O19: =SUMIF('WIP '!$C$5:$N$5,'Summary '!O3,'WIP '!$C$4:$N$4) -> 0 | Q19: =SUM(C19:P19) -> 37583.174 | BJ19: Balance | BK19: =BK17-BK18 -> 2645.6923 | BL19: =BL17-BL18 -> 3429.1538 | BM19: =BM17-BM18 -> 2632.4615 | BN19: =BN17-BN18 -> 3256.1538 | BO19: =BO17-BO18 -> -949.30769 | BP19: =BP17-BP18 -> 2874.3077 | BQ19: =BQ17-BQ18 -> 3926.3846 | BR19: =BR17-BR18 -> 2238.3077 | ... BV19: =BV17-BV18 -> -2188.4615
BJ20: Bal for month | BK20: =BK6-(BK8+BK13+BK18) -> 9710 | BL20: =BL6-(BL8+BL13+BL18) -> 10649 | BM20: =BM6-(BM8+BM13+BM18) -> 9142 | BN20: =BN6-(BN8+BN13+BN18) -> 15072 | BO20: =BO6-(BO8+BO13+BO18) -> 10633 | BP20: =BP6-(BP8+BP13+BP18) -> 14614 | BQ20: =BQ6-(BQ8+BQ13+BQ18) -> 14893 | BR20: =BR6-(BR8+BR13+BR18) -> 14500 | ... BV20: =BV6-(BV8+BV13+BV18) -> -2956
BJ21: Day rate Req | BK21: =BK20/$BX$16 -> 746.92308 | BL21: =BL20/$BX$16 -> 819.15385 | BM21: =BM20/$BX$16 -> 703.23077 | BN21: =BN20/$BX$16 -> 1159.3846 | BO21: =BO20/$BX$16 -> 817.92308 | BP21: =BP20/$BX$16 -> 1124.1538 | BQ21: =BQ20/$BX$16 -> 1145.6154 | BR21: =BR20/$BX$16 -> 1115.3846 | ... BV21: =BV20/$BX$16 -> -227.38462 | BW21: 6 | BX21: =BX7-(BW7+BW12+BW16) -> 6
Y22: Week 2 | BI22: Week 4 | BJ22: Target
BJ23: Actual
Y24: Group | Z24: A1 | AA24: A2 | AB24: A3 | AC24: G1 | AD24: G2 | AE24: G3 | AF24: G4 | AG24: G5 | AH24: G6 | AI24: G7 | AJ24: G8 | AK24: PED | BJ24: Balance
Y25: Target | Z25: =BK12 -> 7291.5789 | AA25: =BL12 -> 7772.2105 | AB25: =BM12 -> 6777.4737 | AC25: =BN12 -> 13089.474 | AD25: =BO12 -> 12179.368 | AE25: =BP12 -> 12804 | AF25: =BQ12 -> 12648.947 | AG25: =BR12 -> 12903.158 | ... AK25: =BV12 -> 1268.8421
Y26: Opening Wip | Z26: ='WIP '!S22 -> 3.6368571 | AA26: ='WIP '!T22 -> 4.4202857 | AB26: ='WIP '!U22 -> 3.7725714 | AC26: ='WIP '!V22 -> 2.8721429 | AD26: ='WIP '!W22 -> 3.3625714 | AE26: ='WIP '!X22 -> 2.4615714 | AF26: ='WIP '!Y22 -> 3.5585714 | AG26: ='WIP '!Z22 -> 4.6878571 | ... AK26: ='WIP '!AD22 -> 1.72
Y27: Fresh input | Z27: ='Input '!AG4 -> 7751 | AA27: ='Input '!AH4 -> 6956 | AB27: ='Input '!AI4 -> 8978 | AC27: ='Input '!AJ4 -> 15697 | AD27: ='Input '!AK4 -> 13610 | AE27: ='Input '!AL4 -> 14812 | AF27: ='Input '!AM4 -> 16391 | AG27: ='Input '!AN4 -> 15072 | ... AK27: ='Input '!AR4 -> 2618
Y28: Returns | Z28: ='Returns '!T42 -> 0 | AA28: ='Returns '!U42 -> 0 | AB28: ='Returns '!V42 -> 0 | AC28: ='Returns '!W42 -> 0 | AD28: ='Returns '!X42 -> 0 | AE28: ='Returns '!Y42 -> 0 | AF28: ='Returns '!Z42 -> 0 | AG28: ='Returns '!AA42 -> 0 | ... AK28: ='Returns '!AE42 -> 0
Y29: Convertible WIP | Z29: =(Z26+Z27)-Z28 -> 7754.6369 | AA29: =(AA26+AA27)-AA28 -> 6960.4203 | AB29: =(AB26+AB27)-AB28 -> 8981.7726 | AC29: =(AC26+AC27)-AC28 -> 15699.872 | AD29: =(AD26+AD27)-AD28 -> 13613.363 | AE29: =(AE26+AE27)-AE28 -> 14814.462 | AF29: =(AF26+AF27)-AF28 -> 16394.559 | AG29: =(AG26+AG27)-AG28 -> 15076.688 | ... AK29: =(AK26+AK27)-AK28 -> 2619.72
Y30: Output | Z30: ='Output '!AA5 -> 7784 | AA30: ='Output '!AB5 -> 8969 | AB30: ='Output '!AC5 -> 7358 | AC30: ='Output '!AD5 -> 15849 | AD30: ='Output '!AE5 -> 13473 | AE30: ='Output '!AF5 -> 15110 | AF30: ='Output '!AG5 -> 16294 | AG30: ='Output '!AH5 -> 14293 | ... AJ30: ='Output '!AK5 -> 14327 | AK30: ='Output '!AM5 -> 5681
C31: No of models | Y31: Balance | Z31: =Z25-Z30 -> -492.42105 | AA31: =AA25-AA30 -> -1196.7895 | AB31: =AB25-AB30 -> -580.52632 | AC31: =AC25-AC30 -> -2759.5263 | AD31: =AD25-AD30 -> -1293.6316 | AE31: =AE25-AE30 -> -2306 | AF31: =AF25-AF30 -> -3645.0526 | AG31: =AG25-AG30 -> -1389.8421 | ... AK31: =AK25-AK30 -> -4412.1579
H32: Tray Size | Y32: Comp % | Z32: =Z30/Z25 -> 1.0675328 | AA32: =AA30/AA25 -> 1.1539832 | AB32: =AB30/AB25 -> 1.0856553 | AC32: =AC30/AC25 -> 1.2108203 | AD32: =AD30/AD25 -> 1.106215 | AE32: =AE30/AE25 -> 1.1801 | AF32: =AF30/AF25 -> 1.2881704 | AG32: =AG30/AG25 -> 1.1077133 | ... AK32: =AK30/AK25 -> 4.4773104
C33: Row Labels | D33: Count of batch | E33: Day Avarage | H33: Sum of Qty | I33: Column Labels
C34: A1 | D34: 188 | E34: =D34/19.5 -> 9.6410256 | H34: Row Labels | I34: JUMBO | J34: NORMAL | K34: (blank) | L34: #N/A | M34: Grand Total | O34: Jumbo | P34: Normal
C35: A2 | D35: 142 | E35: =D35/19.5 -> 7.2820513 | H35: A1 | I35: 20521 | J35: 8863 | M35: 29384 | O35: =I35/M35 -> 0.69837326 | P35: =J35/M35 -> 0.30162674
C36: A3 | D36: 149 | E36: =D36/19.5 -> 7.6410256 | H36: A2 | I36: 13734 | J36: 15346 | M36: 29080 | O36: =I36/M36 -> 0.47228336 | P36: =J36/M36 -> 0.52771664
C37: G1 | D37: 263 | E37: =D37/19.5 -> 13.487179 | H37: A3 | I37: 21161 | J37: 6653 | M37: 27814 | O37: =I37/M37 -> 0.76080391 | P37: =J37/M37 -> 0.23919609
C38: G2 | D38: 205 | E38: =D38/19.5 -> 10.512821 | H38: G1 | I38: 21802 | J38: 24105 | L38: 1037 | M38: 46944 | O38: =I38/M38 -> 0.4644257 | P38: =J38/M38 -> 0.51348415
C39: G3 | D39: 216 | E39: =D39/19.5 -> 11.076923 | H39: G2 | I39: 15611 | J39: 29221 | L39: 1429 | M39: 46261 | O39: =I39/M39 -> 0.33745488 | P39: =J39/M39 -> 0.63165517
C40: G4 | D40: 308 | E40: =D40/19.5 -> 15.794872 | H40: G3 | I40: 19279 | J40: 23052 | L40: 2669 | M40: 45000 | O40: =I40/M40 -> 0.42842222 | P40: =J40/M40 -> 0.51226667
C41: G5 | D41: 208 | E41: =D41/19.5 -> 10.666667 | H41: G4 | I41: 33732 | J41: 14214 | L41: 1000 | M41: 48946 | O41: =I41/M41 -> 0.68916765 | P41: =J41/M41 -> 0.29040167
...

Sheet WIP 
C1: =+C6/1000 -> 3.494 | D1: =+D6/1000 -> 2.719 | E1: =+E6/1000 -> 2.347 | F1: =+F6/1000 -> 3.353 | G1: =+G6/1000 -> 5.662 | H1: =+H6/1000 -> 3.215 | I1: =+I6/1000 -> 3.047 | J1: =+J6/1000 -> 2.996 | ... P1: =+P6/1000 -> 2.869
C4: =AVERAGE(C6:C29) -> 3374.5217 | D4: =AVERAGE(D6:D29) -> 3749.8261 | E4: =AVERAGE(E6:E29) -> 3453.4348 | F4: =AVERAGE(F6:F29) -> 2571.0435 | G4: =AVERAGE(G6:G29) -> 3361.3043 | H4: =AVERAGE(H6:H29) -> 2337.6957 | I4: =AVERAGE(I6:I29) -> 3202.087 | J4: =AVERAGE(J6:J29) -> 4046.1304 | ... P4: =AVERAGE(P6:P29) -> 1907.7826 | R4: Avg WIP
B5: Date | C5: A1 | D5: A2 | E5: A3 | F5: G1 | G5: G2 | H5: G3 | I5: G4 | J5: G5 | K5: G6 | L5: G7 | M5: G8 | N5: KMC | O5: PED | P5: PED-Auto | S5: A1 | T5: A2 | U5: A3 | V5: G1 | W5: G2 | X5: G3 | Y5: G4 | Z5: G5 | AA5: G6 | AB5: G7 | AC5: G8 | AD5: KMC | AE5: PED | AF5: PED-Auto
A6: 1 | B6: 46146 | C6: 3494 | D6: 2719 | E6: 2347 | F6: 3353 | G6: 5662 | H6: 3215 | I6: 3047 | J6: 2996 | K6: 3721 | L6: 4077 | M6: 3565 | N6: 7632 | O6: 3640 | P6: 2869 | R6: Week 1 | S6: =AVERAGE(C6:C9) -> 3591 | T6: =AVERAGE(D6:D9) -> 4037.25 | U6: =AVERAGE(E6:E9) -> 2606.75 | V6: =AVERAGE(F6:F9) -> 3110.5 | W6: =AVERAGE(G6:G9) -> 4540.5 | X6: =AVERAGE(H6:H9) -> 2856.75 | Y6: =AVERAGE(I6:I9) -> 3292.75 | Z6: =AVERAGE(J6:J9) -> 3806.5 | ... AF6: =AVERAGE(P6:P9) -> 2625.5
A7: 2 | B7: 46147 | C7: 4510 | D7: 4082 | E7: 2604 | F7: 3081 | G7: 4802 | H7: 2650 | I7: 4092 | J7: 2924 | K7: 3766 | L7: 4880 | M7: 4216 | N7: 6702 | O7: 3754 | P7: 2851 | R7: Week 2 | S7: =AVERAGE(C10:C16) -> 3636.8571 | T7: =AVERAGE(D10:D16) -> 4420.2857 | U7: =AVERAGE(E10:E16) -> 3772.5714 | V7: =AVERAGE(F10:F16) -> 2872.1429 | W7: =AVERAGE(G10:G16) -> 3362.5714 | X7: =AVERAGE(H10:H16) -> 2461.5714 | Y7: =AVERAGE(I10:I16) -> 3558.5714 | Z7: =AVERAGE(J10:J16) -> 4687.8571 | ... AF7: =AVERAGE(P10:P16) -> 1756.8571
A8: 3 | B8: 46148 | C8: 3180 | D8: 4674 | E8: 2738 | F8: 3004 | G8: 3849 | H8: 2781 | I8: 3016 | J8: 4653 | K8: 3995 | L8: 4356 | M8: 4549 | N8: 1783 | O8: 5352 | P8: 2391 | R8: Week 3 | S8: =AVERAGE(C17:C21) -> 3093.8 | T8: =AVERAGE(D17:D21) -> 2531 | U8: =AVERAGE(E17:E21) -> 3219.2 | V8: =AVERAGE(F17:F21) -> 2131.8 | W8: =AVERAGE(G17:G21) -> 3388 | X8: =AVERAGE(H17:H21) -> 1904.8 | Y8: =AVERAGE(I17:I21) -> 2875.2 | Z8: =AVERAGE(J17:J21) -> 4090.8 | ... AF8: =AVERAGE(P17:P21) -> 1522.6
A9: 4 | B9: 46149 | C9: 3180 | D9: 4674 | E9: 2738 | F9: 3004 | G9: 3849 | H9: 2781 | I9: 3016 | J9: 4653 | K9: 3995 | L9: 4356 | M9: 4549 | N9: 1783 | O9: 5352 | P9: 2391 | R9: Week 4 | S9: =AVERAGE(C22:C28) -> 3189 | T9: =AVERAGE(D22:D28) -> 3785.7143 | U9: =AVERAGE(E22:E28) -> 3785.4286 | V9: =AVERAGE(F22:F28) -> 2275.4286 | W9: =AVERAGE(G22:G28) -> 2667.1429 | X9: =AVERAGE(H22:H28) -> 2226.4286 | Y9: =AVERAGE(I22:I28) -> 3027.2857 | Z9: =AVERAGE(J22:J28) -> 3509.4286 | ... AF9: =AVERAGE(P22:P28) -> 1923.7143
A10: 5 | B10: 46150 | C10: 3510 | D10: 4848 | E10: 3507 | F10: 2711 | G10: 2855 | H10: 2991 | I10: 2276 | J10: 4284 | K10: 2975 | L10: 4258 | M10: 4441 | N10: 4125 | O10: 5489 | P10: 2485
A11: 1 | B11: 46151 | C11: 3291 | D11: 4580 | E11: 4740 | F11: 3425 | G11: 3841 | H11: 2213 | I11: 4138 | J11: 5818 | K11: 4564 | L11: 4737 | M11: 5475 | N11: 2403 | O11: 5398 | P11: 2281
A12: 2 | B12: 46153 | C12: 3859 | D12: 5503 | E12: 4278 | F12: 3345 | G12: 3227 | H12: 2247 | I12: 3983 | J12: 5440 | K12: 4889 | L12: 5062 | M12: 5937 | N12: 2723 | O12: 4051 | P12: 1949
A13: 3 | B13: 46154 | C13: 4338 | D13: 4348 | E13: 3166 | F13: 3465 | G13: 3836 | H13: 2458 | I13: 3879 | J13: 5154 | K13: 5012 | L13: 5246 | M13: 5149 | N13: 266 | O13: 4488 | P13: 1395
A14: 4 | B14: 46155 | C14: 3853 | D14: 5348 | E14: 2710 | F14: 1723 | G14: 2892 | H14: 2686 | I14: 3888 | J14: 4076 | K14: 5285 | L14: 5274 | M14: 5840 | N14: 552 | O14: 4539 | P14: 1747
A15: 5 | B15: 46156 | C15: 3671 | D15: 3868 | E15: 4485 | F15: 1964 | G15: 2910 | H15: 2258 | I15: 4499 | J15: 3649 | K15: 5082 | L15: 4836 | M15: 5706 | N15: 321 | O15: 2223 | P15: 1398
A16: 1 | B16: 46157 | C16: 2936 | D16: 2447 | E16: 3522 | F16: 3472 | G16: 3977 | H16: 2378 | I16: 2247 | J16: 4394 | K16: 3591 | L16: 4642 | M16: 3843 | N16: 1650 | O16: 2134 | P16: 1043
A17: 2 | B17: 46158 | C17: 2523 | D17: 2381 | E17: 2894 | F17: 2362 | G17: 5489 | H17: 2113 | I17: 2662 | J17: 3766 | K17: 2779 | L17: 3318 | M17: 4230 | N17: 2960 | O17: 1887 | P17: 1498
A18: 3 | B18: 46160 | C18: 2947 | D18: 3373 | E18: 3143 | F18: 2518 | G18: 3225 | H18: 1485 | I18: 3909 | J18: 3855 | K18: 3868 | L18: 3523 | M18: 3887 | N18: 1243 | O18: 1714 | P18: 1615
A19: 4 | B19: 46161 | C19: 3427 | D19: 2750 | E19: 3351 | F19: 2434 | G19: 3381 | H19: 693 | I19: 1450 | J19: 5705 | K19: 4000 | L19: 2688 | M19: 3657 | N19: 1492 | O19: 1495 | P19: 1209 | R19: Opening WIP
A20: 5 | B20: 46162 | C20: 3043 | D20: 2004 | E20: 3130 | F20: 3122 | G20: 2768 | H20: 2690 | I20: 3347 | J20: 4136 | K20: 5711 | L20: 1731 | M20: 4266 | N20: 761 | O20: 1423 | P20: 1720 | S20: A1 | T20: A2 | U20: A3 | V20: G1 | W20: G2 | X20: G3 | Y20: G4 | Z20: G5 | AA20: G6 | AB20: G7 | AC20: G8 | AD20: KMC | AE20: PED | AF20: PED-Auto
A21: 6 | B21: 46163 | C21: 3529 | D21: 2147 | E21: 3578 | F21: 223 | G21: 2077 | H21: 2543 | I21: 3008 | J21: 2992 | K21: 4494 | L21: 3096 | M21: 3309 | N21: 0 | O21: 813 | P21: 1571 | R21: Week 1 | S21: =S6/1000 -> 3.591 | T21: =T6/1000 -> 4.03725 | U21: =U6/1000 -> 2.60675 | V21: =V6/1000 -> 3.1105 | W21: =W6/1000 -> 4.5405 | X21: =X6/1000 -> 2.85675 | Y21: =Y6/1000 -> 3.29275 | Z21: =Z6/1000 -> 3.8065 | ... AF21: =AF6/1000 -> 2.6255
A22: 1 | B22: 46164 | C22: 2465 | D22: 2624 | E22: 2100 | F22: 2478 | G22: 1569 | H22: 3147 | I22: 5646 | J22: 3190 | K22: 3258 | L22: 2262 | M22: 4065 | N22: 0 | O22: 560 | P22: 875 | R22: Week 2 | S22: =S7/1000 -> 3.6368571 | T22: =T7/1000 -> 4.4202857 | U22: =U7/1000 -> 3.7725714 | V22: =V7/1000 -> 2.8721429 | W22: =W7/1000 -> 3.3625714 | X22: =X7/1000 -> 2.4615714 | Y22: =Y7/1000 -> 3.5585714 | Z22: =Z7/1000 -> 4.6878571 | ... AF22: =AF7/1000 -> 1.7568571
A23: 2 | B23: 46165 | C23: 2840 | D23: 2646 | E23: 1796 | F23: 1494 | G23: 1756 | H23: 1247 | I23: 2566 | J23: 2953 | K23: 2395 | L23: 1772 | M23: 1985 | N23: 575 | O23: 628 | P23: 1605 | R23: Week 3 | S23: =S8/1000 -> 3.0938 | T23: =T8/1000 -> 2.531 | U23: =U8/1000 -> 3.2192 | V23: =V8/1000 -> 2.1318 | W23: =W8/1000 -> 3.388 | X23: =X8/1000 -> 1.9048 | Y23: =Y8/1000 -> 2.8752 | Z23: =Z8/1000 -> 4.0908 | ... AF23: =AF8/1000 -> 1.5226
A24: 3 | B24: 46167 | C24: 2821 | D24: 3568 | E24: 3202 | F24: 3516 | G24: 2401 | H24: 1882 | I24: 2719 | J24: 3768 | K24: 2751 | L24: 2089 | M24: 3364 | N24: 3508 | O24: 2301 | P24: 1534 | R24: Week 4 | S24: =S9/1000 -> 3.189 | T24: =T9/1000 -> 3.7857143 | U24: =U9/1000 -> 3.7854286 | V24: =V9/1000 -> 2.2754286 | W24: =W9/1000 -> 2.6671429 | X24: =X9/1000 -> 2.2264286 | Y24: =Y9/1000 -> 3.0272857 | Z24: =Z9/1000 -> 3.5094286 | ... AF24: =AF9/1000 -> 1.9237143
A25: 4 | B25: 46168 | C25: 2446 | D25: 2904 | E25: 4197 | F25: 2561 | G25: 2853 | H25: 1654 | I25: 2210 | J25: 2909 | K25: 2055 | L25: 2962 | M25: 2721 | N25: 5030 | O25: 2652 | P25: 2425
A26: 5 | B26: 46169 | C26: 3448 | D26: 3682 | E26: 3439 | F26: 1941 | G26: 2979 | H26: 2428 | I26: 2941 | J26: 4097 | K26: 3467 | L26: 2822 | M26: 2081 | N26: 5823 | O26: 2819 | P26: 2413
A27: 6 | B27: 46171 | C27: 4604 | D27: 5130 | E27: 5110 | F27: 2001 | G27: 3807 | H27: 2402 | I27: 1848 | J27: 4482 | K27: 3543 | L27: 2627 | M27: 2945 | N27: 534 | O27: 2656 | P27: 2704
B28: 46172 | C28: 3699 | D28: 5946 | E28: 6654 | F28: 1937 | G28: 3305 | H28: 2825 | I28: 3261 | J28: 3167 | K28: 2111 | L28: 2646 | M28: 3857 | N28: 2592 | O28: 2781 | P28: 1910
B29: 46173 | S29: A1 | T29: A2 | U29: A3 | V29: G1 | W29: G2 | X29: G3 | Y29: G4 | Z29: G5 | AA29: G6 | AB29: G7 | AC29: G8 | AD29: PED | AE29: KMC | AF29: RET
R30: Week 1 | S30: =S21/1000 -> 0.003591 | T30: =T21/1000 -> 0.00403725 | U30: =U21/1000 -> 0.00260675 | V30: =V21/1000 -> 0.0031105 | W30: =W21/1000 -> 0.0045405 | X30: =X21/1000 -> 0.00285675 | Y30: =Y21/1000 -> 0.00329275 | Z30: =Z21/1000 -> 0.0038065 | ... AF30: =AF21/1000 -> 0.0026255
R31: Week 2 | S31: =S22/1000 -> 0.0036368571 | T31: =T22/1000 -> 0.0044202857 | U31: =U22/1000 -> 0.0037725714 | V31: =V22/1000 -> 0.0028721429 | W31: =W22/1000 -> 0.0033625714 | X31: =X22/1000 -> 0.0024615714 | Y31: =Y22/1000 -> 0.0035585714 | Z31: =Z22/1000 -> 0.0046878571 | ... AF31: =AF22/1000 -> 0.0017568571
R32: Week 3 | S32: =S23/1000 -> 0.0030938 | T32: =T23/1000 -> 0.002531 | U32: =U23/1000 -> 0.0032192 | V32: =V23/1000 -> 0.0021318 | W32: =W23/1000 -> 0.003388 | X32: =X23/1000 -> 0.0019048 | Y32: =Y23/1000 -> 0.0028752 | Z32: =Z23/1000 -> 0.0040908 | ... AF32: =AF23/1000 -> 0.0015226
R33: Week 4 | S33: =S24/1000 -> 0.003189 | T33: =T24/1000 -> 0.0037857143 | U33: =U24/1000 -> 0.0037854286 | V33: =V24/1000 -> 0.0022754286 | W33: =W24/1000 -> 0.0026671429 | X33: =X24/1000 -> 0.0022264286 | Y33: =Y24/1000 -> 0.0030272857 | Z33: =Z24/1000 -> 0.0035094286 | ... AF33: =AF24/1000 -> 0.0019237143

Sheet Input 
A1: Group | B1: Model no | C1: Qty | D1: Date | E1: batch | F1: Base | G1: Len | H1: Process | I1: Lot Size | J1: MG type | K1: Tray Size | O1: Total | P1: =SUBTOTAL(9,P3:P21) -> 22844 | Q1: =SUBTOTAL(9,Q3:Q21) -> 21993 | R1: =SUBTOTAL(9,R3:R21) -> 21182 | S1: =SUBTOTAL(9,S3:S21) -> 40287 | T1: =SUBTOTAL(9,T3:T21) -> 39597 | U1: =SUBTOTAL(9,U3:U21) -> 38817 | V1: =SUBTOTAL(9,V3:V21) -> 43103 | W1: =SUBTOTAL(9,W3:W21) -> 39778 | ... AC1: =SUBTOTAL(9,AC3:AC21) -> 8679
A2: G6 | B2: 10047BAA31/IND | C2: 78 | D2: 46146 | E2: 2 | F2: =IF(ISNUMBER(VALUE(LEFT(B2,5)))=TRUE,LEFT(B2,5),IF(ISNUMBER(VALUE(LEFT(B2,4)))=TRUE,LEFT(B2,4),LEFT(B2,3))) -> 10047 | G2: =LEN(B2) -> 14 | H2: =VLOOKUP(B2,[1]Sheet1!$D:$AB,25,0) -> Regular-Adhe | I2: =LOOKUP(C2, $AY$3:$AY$8, $AZ$3:$AZ$8) -> 51-100 | J2: =VLOOKUP(B2,[1]Sheet1!$D:$Y,22) -> Gask | K2: =VLOOKUP(B2,[1]Sheet1!$D:$AS,42,0) -> JUMBO | O2: Date | P2: A1 | Q2: A2 | R2: A3 | S2: G1 | T2: G2 | U2: G3 | V2: G4 | W2: G5 | X2: G6 | Y2: G7 | Z2: G8 | AA2: KMC | AB2: PED | AC2: PED-Auto | AG2: A1 | AH2: A2 | AI2: A3 | AJ2: G1 | AK2: G2 | AL2: G3 | AM2: G4 | AN2: G5 | AO2: G6 | AP2: G7 | AQ2: G8 | AR2: KMC | AS2: PED | AT2: PED-Auto
A3: G6 | B3: 10047WAA31/IND | C3: 204 | D3: 46146 | E3: 2 | F3: =IF(ISNUMBER(VALUE(LEFT(B3,5)))=TRUE,LEFT(B3,5),IF(ISNUMBER(VALUE(LEFT(B3,4)))=TRUE,LEFT(B3,4),LEFT(B3,3))) -> 10047 | G3: =LEN(B3) -> 14 | H3: =VLOOKUP(B3,[1]Sheet1!$D:$AB,25,0) -> Regular-Adhe | I3: =LOOKUP(C3, $AY$3:$AY$8, $AZ$3:$AZ$8) -> 101-300 | J3: =VLOOKUP(B3,[1]Sheet1!$D:$Y,22) -> Gask | K3: =VLOOKUP(B3,[1]Sheet1!$D:$AS,42,0) -> JUMBO | N3: 1 | O3: 46146 | P3: =SUMIFS($C:$C,$D:$D,$O3,$A:$A,P$2) -> 1512 | Q3: =SUMIFS($C:$C,$D:$D,$O3,$A:$A,Q$2) -> 255 | R3: =SUMIFS($C:$C,$D:$D,$O3,$A:$A,R$2) -> 1109 | S3: =SUMIFS($C:$C,$D:$D,$O3,$A:$A,S$2) -> 2827 | T3: =SUMIFS($C:$C,$D:$D,$O3,$A:$A,T$2) -> 2557 | U3: =SUMIFS($C:$C,$D:$D,$O3,$A:$A,U$2) -> 2094 | V3: =SUMIFS($C:$C,$D:$D,$O3,$A:$A,V$2) -> 2279 | W3: =SUMIFS($C:$C,$D:$D,$O3,$A:$A,W$2) -> 1579 | ... AC3: =SUMIFS($C:$C,$D:$D,$O3,$A:$A,AC$2) -> 915 | AF3: Week 1 | AG3: =SUM(P3:P6) -> 3998 | AH3: =SUM(Q3:Q6) -> 4356 | AI3: =SUM(R3:R6) -> 4102 | AJ3: =SUM(S3:S6) -> 7308 | AK3: =SUM(T3:T6) -> 7329 | AL3: =SUM(U3:U6) -> 7300 | AM3: =SUM(V3:V6) -> 7391 | AN3: =SUM(W3:W6) -> 7179 | ... AT3: =SUM(AC3:AC6) -> 1310 | AY3: 0 | AZ3: 0-50
A4: G6 | B4: 1584SAE00/IND | C4: 387 | D4: 46146 | E4: 1 | F4: =IF(ISNUMBER(VALUE(LEFT(B4,5)))=TRUE,LEFT(B4,5),IF(ISNUMBER(VALUE(LEFT(B4,4)))=TRUE,LEFT(B4,4),LEFT(B4,3))) -> 1584 | G4: =LEN(B4) -> 13 | H4: =VLOOKUP(B4,[1]Sheet1!$D:$AB,25,0) -> Regular-Gask | I4: =LOOKUP(C4, $AY$3:$AY$8, $AZ$3:$AZ$8) -> 301-500 | J4: =VLOOKUP(B4,[1]Sheet1!$D:$Y,22) -> Gask | K4: =VLOOKUP(B4,[1]Sheet1!$D:$AS,42,0) -> JUMBO | N4: 2 | O4: 46147 | P4: =SUMIFS($C:$C,$D:$D,$O4,$A:$A,P$2) -> 324 | Q4: =SUMIFS($C:$C,$D:$D,$O4,$A:$A,Q$2) -> 111 | R4: =SUMIFS($C:$C,$D:$D,$O4,$A:$A,R$2) -> 382 | S4: =SUMIFS($C:$C,$D:$D,$O4,$A:$A,S$2) -> 1227 | T4: =SUMIFS($C:$C,$D:$D,$O4,$A:$A,T$2) -> 1513 | U4: =SUMIFS($C:$C,$D:$D,$O4,$A:$A,U$2) -> 1704 | V4: =SUMIFS($C:$C,$D:$D,$O4,$A:$A,V$2) -> 1445 | W4: =SUMIFS($C:$C,$D:$D,$O4,$A:$A,W$2) -> 1092 | ... AC4: =SUMIFS($C:$C,$D:$D,$O4,$A:$A,AC$2) -> 395 | AF4: Week 2 | AG4: =SUM(P7:P13) -> 7751 | AH4: =SUM(Q7:Q13) -> 6956 | AI4: =SUM(R7:R13) -> 8978 | AJ4: =SUM(S7:S13) -> 15697 | AK4: =SUM(T7:T13) -> 13610 | AL4: =SUM(U7:U13) -> 14812 | AM4: =SUM(V7:V13) -> 16391 | AN4: =SUM(W7:W13) -> 15072 | ... AT4: =SUM(AC7:AC13) -> 2656 | AY4: 51 | AZ4: 51-100
A5: G7 | B5: 1713SAJ00/IND | C5: 267 | D5: 46146 | E5: 1 | F5: =IF(ISNUMBER(VALUE(LEFT(B5,5)))=TRUE,LEFT(B5,5),IF(ISNUMBER(VALUE(LEFT(B5,4)))=TRUE,LEFT(B5,4),LEFT(B5,3))) -> 1713 | G5: =LEN(B5) -> 13 | H5: =VLOOKUP(B5,[1]Sheet1!$D:$AB,25,0) -> Regular-Gask | I5: =LOOKUP(C5, $AY$3:$AY$8, $AZ$3:$AZ$8) -> 101-300 | J5: =VLOOKUP(B5,[1]Sheet1!$D:$Y,22) -> Gask | K5: =VLOOKUP(B5,[1]Sheet1!$D:$AS,42,0) -> JUMBO | N5: 3 | O5: 46148 | P5: =SUMIFS($C:$C,$D:$D,$O5,$A:$A,P$2) -> 1485 | Q5: =SUMIFS($C:$C,$D:$D,$O5,$A:$A,Q$2) -> 1910 | R5: =SUMIFS($C:$C,$D:$D,$O5,$A:$A,R$2) -> 1540 | S5: =SUMIFS($C:$C,$D:$D,$O5,$A:$A,S$2) -> 1425 | T5: =SUMIFS($C:$C,$D:$D,$O5,$A:$A,T$2) -> 1668 | U5: =SUMIFS($C:$C,$D:$D,$O5,$A:$A,U$2) -> 1578 | V5: =SUMIFS($C:$C,$D:$D,$O5,$A:$A,V$2) -> 1886 | W5: =SUMIFS($C:$C,$D:$D,$O5,$A:$A,W$2) -> 1567 | ... AC5: =SUMIFS($C:$C,$D:$D,$O5,$A:$A,AC$2) -> 0 | AF5: Week 3 | AG5: =SUM(P12:P18) -> 7878 | AH5: =SUM(Q12:Q18) -> 7585 | AI5: =SUM(R12:R18) -> 8587 | AJ5: =SUM(S12:S18) -> 15404 | AK5: =SUM(T12:T18) -> 17682 | AL5: =SUM(U12:U18) -> 16293 | AM5: =SUM(V12:V18) -> 17665 | AN5: =SUM(W12:W18) -> 16134 | ... AT5: =SUM(AC12:AC18) -> 2647 | AY5: 101 | AZ5: 101-300
A6: G8 | B6: 1730SAA00/IND | C6: 128 | D6: 46146 | E6: 2 | F6: =IF(ISNUMBER(VALUE(LEFT(B6,5)))=TRUE,LEFT(B6,5),IF(ISNUMBER(VALUE(LEFT(B6,4)))=TRUE,LEFT(B6,4),LEFT(B6,3))) -> 1730 | G6: =LEN(B6) -> 13 | H6: =VLOOKUP(B6,[1]Sheet1!$D:$AB,25,0) -> Regular-Gask | I6: =LOOKUP(C6, $AY$3:$AY$8, $AZ$3:$AZ$8) -> 101-300 | J6: =VLOOKUP(B6,[1]Sheet1!$D:$Y,22) -> Gask | K6: =VLOOKUP(B6,[1]Sheet1!$D:$AS,42,0) -> JUMBO | N6: 4 | O6: 46149 | P6: =SUMIFS($C:$C,$D:$D,$O6,$A:$A,P$2) -> 677 | Q6: =SUMIFS($C:$C,$D:$D,$O6,$A:$A,Q$2) -> 2080 | R6: =SUMIFS($C:$C,$D:$D,$O6,$A:$A,R$2) -> 1071 | S6: =SUMIFS($C:$C,$D:$D,$O6,$A:$A,S$2) -> 1829 | T6: =SUMIFS($C:$C,$D:$D,$O6,$A:$A,T$2) -> 1591 | U6: =SUMIFS($C:$C,$D:$D,$O6,$A:$A,U$2) -> 1924 | V6: =SUMIFS($C:$C,$D:$D,$O6,$A:$A,V$2) -> 1781 | W6: =SUMIFS($C:$C,$D:$D,$O6,$A:$A,W$2) -> 2941 | ... AC6: =SUMIFS($C:$C,$D:$D,$O6,$A:$A,AC$2) -> 0 | AF6: Week 4 | AG6: =SUM(P19:P25) -> 11910 | AH6: =SUM(Q19:Q25) -> 11380 | AI6: =SUM(R19:R25) -> 9020 | AJ6: =SUM(S19:S25) -> 12125 | AK6: =SUM(T19:T25) -> 12211 | AL6: =SUM(U19:U25) -> 10864 | AM6: =SUM(V19:V25) -> 12628 | AN6: =SUM(W19:W25) -> 12480 | ... AT6: =SUM(AC19:AC25) -> 5423 | AY6: 301 | AZ6: 301-500
A7: KMC | B7: 1733KCA32/IND | C7: 199 | D7: 46146 | E7: 1 | F7: =IF(ISNUMBER(VALUE(LEFT(B7,5)))=TRUE,LEFT(B7,5),IF(ISNUMBER(VALUE(LEFT(B7,4)))=TRUE,LEFT(B7,4),LEFT(B7,3))) -> 1733 | G7: =LEN(B7) -> 13 | H7: =VLOOKUP(B7,[1]Sheet1!$D:$AB,25,0) -> MG Adhe + PB Assy + DR Sticker | I7: =LOOKUP(C7, $AY$3:$AY$8, $AZ$3:$AZ$8) -> 101-300 | J7: =VLOOKUP(B7,[1]Sheet1!$D:$Y,22) -> Adhe | K7: =VLOOKUP(B7,[1]Sheet1!$D:$AS,42,0) -> JUMBO | N7: 5 | O7: 46150 | P7: =SUMIFS($C:$C,$D:$D,$O7,$A:$A,P$2) -> 1222 | Q7: =SUMIFS($C:$C,$D:$D,$O7,$A:$A,Q$2) -> 1277 | R7: =SUMIFS($C:$C,$D:$D,$O7,$A:$A,R$2) -> 1719 | S7: =SUMIFS($C:$C,$D:$D,$O7,$A:$A,S$2) -> 2274 | T7: =SUMIFS($C:$C,$D:$D,$O7,$A:$A,T$2) -> 1213 | U7: =SUMIFS($C:$C,$D:$D,$O7,$A:$A,U$2) -> 2646 | V7: =SUMIFS($C:$C,$D:$D,$O7,$A:$A,V$2) -> 2084 | W7: =SUMIFS($C:$C,$D:$D,$O7,$A:$A,W$2) -> 2004 | ... AC7: =SUMIFS($C:$C,$D:$D,$O7,$A:$A,AC$2) -> 855 | AF7: Total | AG7: =SUM(AG3:AG6) -> 31537 | AH7: =SUM(AH3:AH6) -> 30277 | AI7: =SUM(AI3:AI6) -> 30687 | AJ7: =SUM(AJ3:AJ6) -> 50534 | AK7: =SUM(AK3:AK6) -> 50832 | AL7: =SUM(AL3:AL6) -> 49269 | AM7: =SUM(AM3:AM6) -> 54075 | AN7: =SUM(AN3:AN6) -> 50865 | ... AT7: =SUM(AT3:AT6) -> 12036 | AY7: 501 | AZ7: 501-1000
A8: KMC | B8: 1733KCA34/IND | C8: 89 | D8: 46146 | E8: 1 | F8: =IF(ISNUMBER(VALUE(LEFT(B8,5)))=TRUE,LEFT(B8,5),IF(ISNUMBER(VALUE(LEFT(B8,4)))=TRUE,LEFT(B8,4),LEFT(B8,3))) -> 1733 | G8: =LEN(B8) -> 13 | H8: =VLOOKUP(B8,[1]Sheet1!$D:$AB,25,0) -> MG Adhe + PB Assy + DR Sticker | I8: =LOOKUP(C8, $AY$3:$AY$8, $AZ$3:$AZ$8) -> 51-100 | J8: =VLOOKUP(B8,[1]Sheet1!$D:$Y,22) -> Adhe | K8: =VLOOKUP(B8,[1]Sheet1!$D:$AS,42,0) -> NORMAL | N8: 1 | O8: 46151 | P8: =SUMIFS($C:$C,$D:$D,$O8,$A:$A,P$2) -> 1547 | Q8: =SUMIFS($C:$C,$D:$D,$O8,$A:$A,Q$2) -> 429 | R8: =SUMIFS($C:$C,$D:$D,$O8,$A:$A,R$2) -> 1943 | S8: =SUMIFS($C:$C,$D:$D,$O8,$A:$A,S$2) -> 2856 | T8: =SUMIFS($C:$C,$D:$D,$O8,$A:$A,T$2) -> 3278 | U8: =SUMIFS($C:$C,$D:$D,$O8,$A:$A,U$2) -> 1609 | V8: =SUMIFS($C:$C,$D:$D,$O8,$A:$A,V$2) -> 3195 | W8: =SUMIFS($C:$C,$D:$D,$O8,$A:$A,W$2) -> 2570 | ... AC8: =SUMIFS($C:$C,$D:$D,$O8,$A:$A,AC$2) -> 0 | AY8: 1001 | AZ8: 1000more
A9: G3 | B9: 1767SED31/IND | C9: 85 | D9: 46146 | E9: 1 | F9: =IF(ISNUMBER(VALUE(LEFT(B9,5)))=TRUE,LEFT(B9,5),IF(ISNUMBER(VALUE(LEFT(B9,4)))=TRUE,LEFT(B9,4),LEFT(B9,3))) -> 1767 | G9: =LEN(B9) -> 13 | H9: =VLOOKUP(B9,[1]Sheet1!$D:$AB,25,0) -> Regular-Adhe | I9: =LOOKUP(C9, $AY$3:$AY$8, $AZ$3:$AZ$8) -> 51-100 | J9: =VLOOKUP(B9,[1]Sheet1!$D:$Y,22) -> Adhe | K9: =VLOOKUP(B9,[1]Sheet1!$D:$AS,42,0) -> JUMBO | N9: 2 | O9: 46153 | P9: =SUMIFS($C:$C,$D:$D,$O9,$A:$A,P$2) -> 1189 | Q9: =SUMIFS($C:$C,$D:$D,$O9,$A:$A,Q$2) -> 1772 | R9: =SUMIFS($C:$C,$D:$D,$O9,$A:$A,R$2) -> 1262 | S9: =SUMIFS($C:$C,$D:$D,$O9,$A:$A,S$2) -> 2348 | T9: =SUMIFS($C:$C,$D:$D,$O9,$A:$A,T$2) -> 968 | U9: =SUMIFS($C:$C,$D:$D,$O9,$A:$A,U$2) -> 2215 | V9: =SUMIFS($C:$C,$D:$D,$O9,$A:$A,V$2) -> 1909 | W9: =SUMIFS($C:$C,$D:$D,$O9,$A:$A,W$2) -> 2337 | ... AC9: =SUMIFS($C:$C,$D:$D,$O9,$A:$A,AC$2) -> 0
A10: A3 | B10: 1767SED31/IND | C10: 791 | D10: 46146 | E10: 2 | F10: =IF(ISNUMBER(VALUE(LEFT(B10,5)))=TRUE,LEFT(B10,5),IF(ISNUMBER(VALUE(LEFT(B10,4)))=TRUE,LEFT(B10,4),LEFT(B10,3))) -> 1767 | G10: =LEN(B10) -> 13 | H10: =VLOOKUP(B10,[1]Sheet1!$D:$AB,25,0) -> Regular-Adhe | I10: =LOOKUP(C10, $AY$3:$AY$8, $AZ$3:$AZ$8) -> 501-1000 | J10: =VLOOKUP(B10,[1]Sheet1!$D:$Y,22) -> Adhe | K10: =VLOOKUP(B10,[1]Sheet1!$D:$AS,42,0) -> JUMBO | N10: 3 | O10: 46154 | P10: =SUMIFS($C:$C,$D:$D,$O10,$A:$A,P$2) -> 1184 | Q10: =SUMIFS($C:$C,$D:$D,$O10,$A:$A,Q$2) -> 171 | R10: =SUMIFS($C:$C,$D:$D,$O10,$A:$A,R$2) -> 685 | S10: =SUMIFS($C:$C,$D:$D,$O10,$A:$A,S$2) -> 2397 | T10: =SUMIFS($C:$C,$D:$D,$O10,$A:$A,T$2) -> 1726 | U10: =SUMIFS($C:$C,$D:$D,$O10,$A:$A,U$2) -> 2013 | V10: =SUMIFS($C:$C,$D:$D,$O10,$A:$A,V$2) -> 2251 | W10: =SUMIFS($C:$C,$D:$D,$O10,$A:$A,W$2) -> 2407 | ... AC10: =SUMIFS($C:$C,$D:$D,$O10,$A:$A,AC$2) -> 692 | AG10: A1 | AH10: A2 | AI10: A3 | AJ10: G1 | AK10: G2 | AL10: G3 | AM10: G4 | AN10: G5 | AO10: G6 | AP10: G7 | AQ10: G8 | AR10: KMC | AS10: PED | AT10: PED-Auto
A11: G8 | B11: 1773NAA31/IND | C11: 57 | D11: 46146 | E11: 2 | F11: =IF(ISNUMBER(VALUE(LEFT(B11,5)))=TRUE,LEFT(B11,5),IF(ISNUMBER(VALUE(LEFT(B11,4)))=TRUE,LEFT(B11,4),LEFT(B11,3))) -> 1773 | G11: =LEN(B11) -> 13 | H11: =VLOOKUP(B11,[1]Sheet1!$D:$AB,25,0) -> Regular-Gask | I11: =LOOKUP(C11, $AY$3:$AY$8, $AZ$3:$AZ$8) -> 51-100 | J11: =VLOOKUP(B11,[1]Sheet1!$D:$Y,22) -> Gask | K11: =VLOOKUP(B11,[1]Sheet1!$D:$AS,42,0) -> JUMBO | N11: 4 | O11: 46155 | P11: =SUMIFS($C:$C,$D:$D,$O11,$A:$A,P$2) -> 456 | Q11: =SUMIFS($C:$C,$D:$D,$O11,$A:$A,Q$2) -> 2110 | R11: =SUMIFS($C:$C,$D:$D,$O11,$A:$A,R$2) -> 496 | S11: =SUMIFS($C:$C,$D:$D,$O11,$A:$A,S$2) -> 2232 | T11: =SUMIFS($C:$C,$D:$D,$O11,$A:$A,T$2) -> 1854 | U11: =SUMIFS($C:$C,$D:$D,$O11,$A:$A,U$2) -> 2060 | V11: =SUMIFS($C:$C,$D:$D,$O11,$A:$A,V$2) -> 1823 | W11: =SUMIFS($C:$C,$D:$D,$O11,$A:$A,W$2) -> 1889 | ... AC11: =SUMIFS($C:$C,$D:$D,$O11,$A:$A,AC$2) -> 1109 | AF11: Week 1 | AG11: =AG3/1000 -> 3.998 | AH11: =AH3/1000 -> 4.356 | AI11: =AI3/1000 -> 4.102 | AJ11: =AJ3/1000 -> 7.308 | AK11: =AK3/1000 -> 7.329 | AL11: =AL3/1000 -> 7.3 | AM11: =AM3/1000 -> 7.391 | AN11: =AN3/1000 -> 7.179 | ... AT11: =AT3/1000 -> 1.31
A12: G8 | B12: 1802SAE30/IND | C12: 1015 | D12: 46146 | E12: 1 | F12: =IF(ISNUMBER(VALUE(LEFT(B12,5)))=TRUE,LEFT(B12,5),IF(ISNUMBER(VALUE(LEFT(B12,4)))=TRUE,LEFT(B12,4),LEFT(B12,3))) -> 1802 | G12: =LEN(B12) -> 13 | H12: =VLOOKUP(B12,[1]Sheet1!$D:$AB,25,0) -> Regular-Gask | I12: =LOOKUP(C12, $AY$3:$AY$8, $AZ$3:$AZ$8) -> 1000more | J12: =VLOOKUP(B12,[1]Sheet1!$D:$Y,22) -> Gask | K12: =VLOOKUP(B12,[1]Sheet1!$D:$AS,42,0) -> JUMBO | N12: 5 | O12: 46156 | P12: =SUMIFS($C:$C,$D:$D,$O12,$A:$A,P$2) -> 1428 | Q12: =SUMIFS($C:$C,$D:$D,$O12,$A:$A,Q$2) -> 611 | R12: =SUMIFS($C:$C,$D:$D,$O12,$A:$A,R$2) -> 2498 | S12: =SUMIFS($C:$C,$D:$D,$O12,$A:$A,S$2) -> 1569 | T12: =SUMIFS($C:$C,$D:$D,$O12,$A:$A,T$2) -> 1974 | U12: =SUMIFS($C:$C,$D:$D,$O12,$A:$A,U$2) -> 1921 | V12: =SUMIFS($C:$C,$D:$D,$O12,$A:$A,V$2) -> 2813 | W12: =SUMIFS($C:$C,$D:$D,$O12,$A:$A,W$2) -> 1885 | ... AC12: =SUMIFS($C:$C,$D:$D,$O12,$A:$A,AC$2) -> 0 | AF12: Week 2 | AG12: =AG4/1000 -> 7.751 | AH12: =AH4/1000 -> 6.956 | AI12: =AI4/1000 -> 8.978 | AJ12: =AJ4/1000 -> 15.697 | AK12: =AK4/1000 -> 13.61 | AL12: =AL4/1000 -> 14.812 | AM12: =AM4/1000 -> 16.391 | AN12: =AN4/1000 -> 15.072 | ... AT12: =AT4/1000 -> 2.656
A13: G1 | B13: 1802SAE30/IND | C13: 1253 | D13: 46146 | E13: 2 | F13: =IF(ISNUMBER(VALUE(LEFT(B13,5)))=TRUE,LEFT(B13,5),IF(ISNUMBER(VALUE(LEFT(B13,4)))=TRUE,LEFT(B13,4),LEFT(B13,3))) -> 1802 | G13: =LEN(B13) -> 13 | H13: =VLOOKUP(B13,[1]Sheet1!$D:$AB,25,0) -> Regular-Gask | I13: =LOOKUP(C13, $AY$3:$AY$8, $AZ$3:$AZ$8) -> 1000more | J13: =VLOOKUP(B13,[1]Sheet1!$D:$Y,22) -> Gask | K13: =VLOOKUP(B13,[1]Sheet1!$D:$AS,42,0) -> JUMBO | N13: 1 | O13: 46157 | P13: =SUMIFS($C:$C,$D:$D,$O13,$A:$A,P$2) -> 725 | Q13: =SUMIFS($C:$C,$D:$D,$O13,$A:$A,Q$2) -> 586 | R13: =SUMIFS($C:$C,$D:$D,$O13,$A:$A,R$2) -> 375 | S13: =SUMIFS($C:$C,$D:$D,$O13,$A:$A,S$2) -> 2021 | T13: =SUMIFS($C:$C,$D:$D,$O13,$A:$A,T$2) -> 2597 | U13: =SUMIFS($C:$C,$D:$D,$O13,$A:$A,U$2) -> 2348 | V13: =SUMIFS($C:$C,$D:$D,$O13,$A:$A,V$2) -> 2316 | W13: =SUMIFS($C:$C,$D:$D,$O13,$A:$A,W$2) -> 1980 | ... AC13: =SUMIFS($C:$C,$D:$D,$O13,$A:$A,AC$2) -> 0 | AF13: Week 3 | AG13: =AG5/1000 -> 7.878 | AH13: =AH5/1000 -> 7.585 | AI13: =AI5/1000 -> 8.587 | AJ13: =AJ5/1000 -> 15.404 | AK13: =AK5/1000 -> 17.682 | AL13: =AL5/1000 -> 16.293 | AM13: =AM5/1000 -> 17.665 | AN13: =AN5/1000 -> 16.134 | ... AT13: =AT5/1000 -> 2.647
A14: KMC | B14: 1805SAK31/IND | C14: 321 | D14: 46146 | E14: 1 | F14: =IF(ISNUMBER(VALUE(LEFT(B14,5)))=TRUE,LEFT(B14,5),IF(ISNUMBER(VALUE(LEFT(B14,4)))=TRUE,LEFT(B14,4),LEFT(B14,3))) -> 1805 | G14: =LEN(B14) -> 13 | H14: =VLOOKUP(B14,[1]Sheet1!$D:$AB,25,0) -> MG Adhe + PB assembly | I14: =LOOKUP(C14, $AY$3:$AY$8, $AZ$3:$AZ$8) -> 301-500 | J14: =VLOOKUP(B14,[1]Sheet1!$D:$Y,22) -> Adhe | K14: =VLOOKUP(B14,[1]Sheet1!$D:$AS,42,0) -> JUMBO | N14: 2 | O14: 46158 | P14: =SUMIFS($C:$C,$D:$D,$O14,$A:$A,P$2) -> 695 | Q14: =SUMIFS($C:$C,$D:$D,$O14,$A:$A,Q$2) -> 1001 | R14: =SUMIFS($C:$C,$D:$D,$O14,$A:$A,R$2) -> 716 | S14: =SUMIFS($C:$C,$D:$D,$O14,$A:$A,S$2) -> 2623 | T14: =SUMIFS($C:$C,$D:$D,$O14,$A:$A,T$2) -> 4271 | U14: =SUMIFS($C:$C,$D:$D,$O14,$A:$A,U$2) -> 2589 | V14: =SUMIFS($C:$C,$D:$D,$O14,$A:$A,V$2) -> 2537 | W14: =SUMIFS($C:$C,$D:$D,$O14,$A:$A,W$2) -> 1979 | ... AC14: =SUMIFS($C:$C,$D:$D,$O14,$A:$A,AC$2) -> 945 | AF14: Week 4 | AG14: =AG6/1000 -> 11.91 | AH14: =AH6/1000 -> 11.38 | AI14: =AI6/1000 -> 9.02 | AJ14: =AJ6/1000 -> 12.125 | AK14: =AK6/1000 -> 12.211 | AL14: =AL6/1000 -> 10.864 | AM14: =AM6/1000 -> 12.628 | AN14: =AN6/1000 -> 12.48 | ... AT14: =AT6/1000 -> 5.423
A15: KMC | B15: 1805SAK31/IND | C15: 95 | D15: 46146 | E15: 2 | F15: =IF(ISNUMBER(VALUE(LEFT(B15,5)))=TRUE,LEFT(B15,5),IF(ISNUMBER(VALUE(LEFT(B15,4)))=TRUE,LEFT(B15,4),LEFT(B15,3))) -> 1805 | G15: =LEN(B15) -> 13 | H15: =VLOOKUP(B15,[1]Sheet1!$D:$AB,25,0) -> MG Adhe + PB assembly | I15: =LOOKUP(C15, $AY$3:$AY$8, $AZ$3:$AZ$8) -> 51-100 | J15: =VLOOKUP(B15,[1]Sheet1!$D:$Y,22) -> Adhe | K15: =VLOOKUP(B15,[1]Sheet1!$D:$AS,42,0) -> JUMBO | N15: 3 | O15: 46160 | P15: =SUMIFS($C:$C,$D:$D,$O15,$A:$A,P$2) -> 1645 | Q15: =SUMIFS($C:$C,$D:$D,$O15,$A:$A,Q$2) -> 2009 | R15: =SUMIFS($C:$C,$D:$D,$O15,$A:$A,R$2) -> 750 | S15: =SUMIFS($C:$C,$D:$D,$O15,$A:$A,S$2) -> 3145 | T15: =SUMIFS($C:$C,$D:$D,$O15,$A:$A,T$2) -> 1861 | U15: =SUMIFS($C:$C,$D:$D,$O15,$A:$A,U$2) -> 2570 | V15: =SUMIFS($C:$C,$D:$D,$O15,$A:$A,V$2) -> 3344 | W15: =SUMIFS($C:$C,$D:$D,$O15,$A:$A,W$2) -> 3026 | ... AC15: =SUMIFS($C:$C,$D:$D,$O15,$A:$A,AC$2) -> 1040 | AF15: Total | AG15: =SUM(AG11:AG14) -> 31.537 | AH15: =SUM(AH11:AH14) -> 30.277 | AI15: =SUM(AI11:AI14) -> 30.687 | AJ15: =SUM(AJ11:AJ14) -> 50.534 | AK15: =SUM(AK11:AK14) -> 50.832 | AL15: =SUM(AL11:AL14) -> 49.269 | AM15: =SUM(AM11:AM14) -> 54.075 | AN15: =SUM(AN11:AN14) -> 50.865 | ... AT15: =SUM(AT11:AT14) -> 12.036
A16: G2 | B16: 1824BAA40/IND | C16: 185 | D16: 46146 | E16: 1 | F16: =IF(ISNUMBER(VALUE(LEFT(B16,5)))=TRUE,LEFT(B16,5),IF(ISNUMBER(VALUE(LEFT(B16,4)))=TRUE,LEFT(B16,4),LEFT(B16,3))) -> 1824 | G16: =LEN(B16) -> 13 | H16: =VLOOKUP(B16,[1]Sheet1!$D:$AB,25,0) -> Regular-Gask | I16: =LOOKUP(C16, $AY$3:$AY$8, $AZ$3:$AZ$8) -> 101-300 | J16: =VLOOKUP(B16,[1]Sheet1!$D:$Y,22) -> Gask | K16: =VLOOKUP(B16,[1]Sheet1!$D:$AS,42,0) -> JUMBO | N16: 4 | O16: 46161 | P16: =SUMIFS($C:$C,$D:$D,$O16,$A:$A,P$2) -> 915 | Q16: =SUMIFS($C:$C,$D:$D,$O16,$A:$A,Q$2) -> 424 | R16: =SUMIFS($C:$C,$D:$D,$O16,$A:$A,R$2) -> 1383 | S16: =SUMIFS($C:$C,$D:$D,$O16,$A:$A,S$2) -> 1892 | T16: =SUMIFS($C:$C,$D:$D,$O16,$A:$A,T$2) -> 3000 | U16: =SUMIFS($C:$C,$D:$D,$O16,$A:$A,U$2) -> 1721 | V16: =SUMIFS($C:$C,$D:$D,$O16,$A:$A,V$2) -> 1736 | W16: =SUMIFS($C:$C,$D:$D,$O16,$A:$A,W$2) -> 3060 | ... AC16: =SUMIFS($C:$C,$D:$D,$O16,$A:$A,AC$2) -> 0
A17: G2 | B17: 1824BAB00/IND | C17: 291 | D17: 46146 | E17: 1 | F17: =IF(ISNUMBER(VALUE(LEFT(B17,5)))=TRUE,LEFT(B17,5),IF(ISNUMBER(VALUE(LEFT(B17,4)))=TRUE,LEFT(B17,4),LEFT(B17,3))) -> 1824 | G17: =LEN(B17) -> 13 | H17: =VLOOKUP(B17,[1]Sheet1!$D:$AB,25,0) -> Regular-Gask | I17: =LOOKUP(C17, $AY$3:$AY$8, $AZ$3:$AZ$8) -> 101-300 | J17: =VLOOKUP(B17,[1]Sheet1!$D:$Y,22) -> Gask | K17: =VLOOKUP(B17,[1]Sheet1!$D:$AS,42,0) -> JUMBO | N17: 5 | O17: 46162 | P17: =SUMIFS($C:$C,$D:$D,$O17,$A:$A,P$2) -> 917 | Q17: =SUMIFS($C:$C,$D:$D,$O17,$A:$A,Q$2) -> 1619 | R17: =SUMIFS($C:$C,$D:$D,$O17,$A:$A,R$2) -> 1377 | S17: =SUMIFS($C:$C,$D:$D,$O17,$A:$A,S$2) -> 2798 | T17: =SUMIFS($C:$C,$D:$D,$O17,$A:$A,T$2) -> 2910 | U17: =SUMIFS($C:$C,$D:$D,$O17,$A:$A,U$2) -> 3416 | V17: =SUMIFS($C:$C,$D:$D,$O17,$A:$A,V$2) -> 2932 | W17: =SUMIFS($C:$C,$D:$D,$O17,$A:$A,W$2) -> 2787 | ... AC17: =SUMIFS($C:$C,$D:$D,$O17,$A:$A,AC$2) -> 662
A18: G2 | B18: 1824NAB00/IND | C18: 373 | D18: 46146 | E18: 1 | F18: =IF(ISNUMBER(VALUE(LEFT(B18,5)))=TRUE,LEFT(B18,5),IF(ISNUMBER(VALUE(LEFT(B18,4)))=TRUE,LEFT(B18,4),LEFT(B18,3))) -> 1824 | G18: =LEN(B18) -> 13 | H18: =VLOOKUP(B18,[1]Sheet1!$D:$AB,25,0) -> Regular-Gask | I18: =LOOKUP(C18, $AY$3:$AY$8, $AZ$3:$AZ$8) -> 301-500 | J18: =VLOOKUP(B18,[1]Sheet1!$D:$Y,22) -> Gask | K18: =VLOOKUP(B18,[1]Sheet1!$D:$AS,42,0) -> JUMBO | N18: 6 | O18: 46163 | P18: =SUMIFS($C:$C,$D:$D,$O18,$A:$A,P$2) -> 1553 | Q18: =SUMIFS($C:$C,$D:$D,$O18,$A:$A,Q$2) -> 1335 | R18: =SUMIFS($C:$C,$D:$D,$O18,$A:$A,R$2) -> 1488 | S18: =SUMIFS($C:$C,$D:$D,$O18,$A:$A,S$2) -> 1356 | T18: =SUMIFS($C:$C,$D:$D,$O18,$A:$A,T$2) -> 1069 | U18: =SUMIFS($C:$C,$D:$D,$O18,$A:$A,U$2) -> 1728 | V18: =SUMIFS($C:$C,$D:$D,$O18,$A:$A,V$2) -> 1987 | W18: =SUMIFS($C:$C,$D:$D,$O18,$A:$A,W$2) -> 1417 | ... AC18: =SUMIFS($C:$C,$D:$D,$O18,$A:$A,AC$2) -> 0 | AK18: No of models
A19: G1 | B19: 1825BAA00/IND | C19: 108 | D19: 46146 | E19: 2 | F19: =IF(ISNUMBER(VALUE(LEFT(B19,5)))=TRUE,LEFT(B19,5),IF(ISNUMBER(VALUE(LEFT(B19,4)))=TRUE,LEFT(B19,4),LEFT(B19,3))) -> 1825 | G19: =LEN(B19) -> 13 | H19: =VLOOKUP(B19,[1]Sheet1!$D:$AB,25,0) -> Regular-Gask | I19: =LOOKUP(C19, $AY$3:$AY$8, $AZ$3:$AZ$8) -> 101-300 | J19: =VLOOKUP(B19,[1]Sheet1!$D:$Y,22) -> Gask | K19: =VLOOKUP(B19,[1]Sheet1!$D:$AS,42,0) -> JUMBO | N19: 1 | O19: 46164 | P19: =SUMIFS($C:$C,$D:$D,$O19,$A:$A,P$2) -> 1006 | Q19: =SUMIFS($C:$C,$D:$D,$O19,$A:$A,Q$2) -> 731 | R19: =SUMIFS($C:$C,$D:$D,$O19,$A:$A,R$2) -> 218 | S19: =SUMIFS($C:$C,$D:$D,$O19,$A:$A,S$2) -> 2108 | T19: =SUMIFS($C:$C,$D:$D,$O19,$A:$A,T$2) -> 2179 | U19: =SUMIFS($C:$C,$D:$D,$O19,$A:$A,U$2) -> 1881 | V19: =SUMIFS($C:$C,$D:$D,$O19,$A:$A,V$2) -> 2487 | W19: =SUMIFS($C:$C,$D:$D,$O19,$A:$A,W$2) -> 1908 | ... AC19: =SUMIFS($C:$C,$D:$D,$O19,$A:$A,AC$2) -> 0
A20: G1 | B20: 1825SAC00/IND | C20: 160 | D20: 46146 | E20: 1 | F20: =IF(ISNUMBER(VALUE(LEFT(B20,5)))=TRUE,LEFT(B20,5),IF(ISNUMBER(VALUE(LEFT(B20,4)))=TRUE,LEFT(B20,4),LEFT(B20,3))) -> 1825 | G20: =LEN(B20) -> 13 | H20: =VLOOKUP(B20,[1]Sheet1!$D:$AB,25,0) -> Regular-Gask | I20: =LOOKUP(C20, $AY$3:$AY$8, $AZ$3:$AZ$8) -> 101-300 | J20: =VLOOKUP(B20,[1]Sheet1!$D:$Y,22) -> Gask | K20: =VLOOKUP(B20,[1]Sheet1!$D:$AS,42,0) -> JUMBO | N20: 2 | O20: 46165 | P20: =SUMIFS($C:$C,$D:$D,$O20,$A:$A,P$2) -> 2182 | Q20: =SUMIFS($C:$C,$D:$D,$O20,$A:$A,Q$2) -> 1781 | R20: =SUMIFS($C:$C,$D:$D,$O20,$A:$A,R$2) -> 1085 | S20: =SUMIFS($C:$C,$D:$D,$O20,$A:$A,S$2) -> 1680 | T20: =SUMIFS($C:$C,$D:$D,$O20,$A:$A,T$2) -> 1684 | U20: =SUMIFS($C:$C,$D:$D,$O20,$A:$A,U$2) -> 1400 | V20: =SUMIFS($C:$C,$D:$D,$O20,$A:$A,V$2) -> 2149 | W20: =SUMIFS($C:$C,$D:$D,$O20,$A:$A,W$2) -> 1675 | ... AC20: =SUMIFS($C:$C,$D:$D,$O20,$A:$A,AC$2) -> 1033
A21: G1 | B21: 1825WAA40/IND | C21: 139 | D21: 46146 | E21: 1 | F21: =IF(ISNUMBER(VALUE(LEFT(B21,5)))=TRUE,LEFT(B21,5),IF(ISNUMBER(VALUE(LEFT(B21,4)))=TRUE,LEFT(B21,4),LEFT(B21,3))) -> 1825 | G21: =LEN(B21) -> 13 | H21: =VLOOKUP(B21,[1]Sheet1!$D:$AB,25,0) -> Regular-Gask | I21: =LOOKUP(C21, $AY$3:$AY$8, $AZ$3:$AZ$8) -> 101-300 | J21: =VLOOKUP(B21,[1]Sheet1!$D:$Y,22) -> Gask | K21: =VLOOKUP(B21,[1]Sheet1!$D:$AS,42,0) -> JUMBO | N21: 3 | O21: 46167 | P21: =SUMIFS($C:$C,$D:$D,$O21,$A:$A,P$2) -> 2182 | Q21: =SUMIFS($C:$C,$D:$D,$O21,$A:$A,Q$2) -> 1781 | R21: =SUMIFS($C:$C,$D:$D,$O21,$A:$A,R$2) -> 1085 | S21: =SUMIFS($C:$C,$D:$D,$O21,$A:$A,S$2) -> 1680 | T21: =SUMIFS($C:$C,$D:$D,$O21,$A:$A,T$2) -> 1684 | U21: =SUMIFS($C:$C,$D:$D,$O21,$A:$A,U$2) -> 1400 | V21: =SUMIFS($C:$C,$D:$D,$O21,$A:$A,V$2) -> 2149 | W21: =SUMIFS($C:$C,$D:$D,$O21,$A:$A,W$2) -> 1675 | ... AC21: =SUMIFS($C:$C,$D:$D,$O21,$A:$A,AC$2) -> 1033
A22: PED-AUTO | B22: 1845WAA31/IND | C22: 231 | D22: 46146 | E22: 2 | F22: =IF(ISNUMBER(VALUE(LEFT(B22,5)))=TRUE,LEFT(B22,5),IF(ISNUMBER(VALUE(LEFT(B22,4)))=TRUE,LEFT(B22,4),LEFT(B22,3))) -> 1845 | G22: =LEN(B22) -> 13 | H22: =VLOOKUP(B22,[1]Sheet1!$D:$AB,25,0) -> Regular-Adhe | I22: =LOOKUP(C22, $AY$3:$AY$8, $AZ$3:$AZ$8) -> 101-300 | J22: =VLOOKUP(B22,[1]Sheet1!$D:$Y,22) -> Adhe | K22: =VLOOKUP(B22,[1]Sheet1!$D:$AS,42,0) -> JUMBO | N22: 4 | O22: 46168 | P22: =SUMIFS($C:$C,$D:$D,$O22,$A:$A,P$2) -> 869 | Q22: =SUMIFS($C:$C,$D:$D,$O22,$A:$A,Q$2) -> 1015 | R22: =SUMIFS($C:$C,$D:$D,$O22,$A:$A,R$2) -> 1224 | S22: =SUMIFS($C:$C,$D:$D,$O22,$A:$A,S$2) -> 1659 | T22: =SUMIFS($C:$C,$D:$D,$O22,$A:$A,T$2) -> 1663 | U22: =SUMIFS($C:$C,$D:$D,$O22,$A:$A,U$2) -> 1494 | V22: =SUMIFS($C:$C,$D:$D,$O22,$A:$A,V$2) -> 1472 | W22: =SUMIFS($C:$C,$D:$D,$O22,$A:$A,W$2) -> 1354 | ... AC22: =SUMIFS($C:$C,$D:$D,$O22,$A:$A,AC$2) -> 953
A23: G1 | B23: 2418YAC00/IND | C23: 53 | D23: 46146 | E23: 2 | F23: =IF(ISNUMBER(VALUE(LEFT(B23,5)))=TRUE,LEFT(B23,5),IF(ISNUMBER(VALUE(LEFT(B23,4)))=TRUE,LEFT(B23,4),LEFT(B23,3))) -> 2418 | G23: =LEN(B23) -> 13 | H23: =VLOOKUP(B23,[1]Sheet1!$D:$AB,25,0) -> Regular-Adhe | I23: =LOOKUP(C23, $AY$3:$AY$8, $AZ$3:$AZ$8) -> 51-100 | J23: =VLOOKUP(B23,[1]Sheet1!$D:$Y,22) -> Adhe | K23: =VLOOKUP(B23,[1]Sheet1!$D:$AS,42,0) -> NORMAL | N23: 5 | O23: 46169 | P23: =SUMIFS($C:$C,$D:$D,$O23,$A:$A,P$2) -> 1887 | Q23: =SUMIFS($C:$C,$D:$D,$O23,$A:$A,Q$2) -> 1818 | R23: =SUMIFS($C:$C,$D:$D,$O23,$A:$A,R$2) -> 2086 | S23: =SUMIFS($C:$C,$D:$D,$O23,$A:$A,S$2) -> 2590 | T23: =SUMIFS($C:$C,$D:$D,$O23,$A:$A,T$2) -> 2553 | U23: =SUMIFS($C:$C,$D:$D,$O23,$A:$A,U$2) -> 2398 | V23: =SUMIFS($C:$C,$D:$D,$O23,$A:$A,V$2) -> 2041 | W23: =SUMIFS($C:$C,$D:$D,$O23,$A:$A,W$2) -> 2721 | ... AC23: =SUMIFS($C:$C,$D:$D,$O23,$A:$A,AC$2) -> 1079
A24: G6 | B24: 2579QAC31/IND | C24: 56 | D24: 46146 | E24: 2 | F24: =IF(ISNUMBER(VALUE(LEFT(B24,5)))=TRUE,LEFT(B24,5),IF(ISNUMBER(VALUE(LEFT(B24,4)))=TRUE,LEFT(B24,4),LEFT(B24,3))) -> 2579 | G24: =LEN(B24) -> 13 | H24: =VLOOKUP(B24,[1]Sheet1!$D:$AB,25,0) -> Regular-Adhe | I24: =LOOKUP(C24, $AY$3:$AY$8, $AZ$3:$AZ$8) -> 51-100 | J24: =VLOOKUP(B24,[1]Sheet1!$D:$Y,22) -> Adhe | K24: =VLOOKUP(B24,[1]Sheet1!$D:$AS,42,0) -> NORMAL | N24: 6 | O24: 46171 | P24: =SUMIFS($C:$C,$D:$D,$O24,$A:$A,P$2) -> 2845 | Q24: =SUMIFS($C:$C,$D:$D,$O24,$A:$A,Q$2) -> 2720 | R24: =SUMIFS($C:$C,$D:$D,$O24,$A:$A,R$2) -> 3289 | S24: =SUMIFS($C:$C,$D:$D,$O24,$A:$A,S$2) -> 1785 | T24: =SUMIFS($C:$C,$D:$D,$O24,$A:$A,T$2) -> 2113 | U24: =SUMIFS($C:$C,$D:$D,$O24,$A:$A,U$2) -> 2153 | V24: =SUMIFS($C:$C,$D:$D,$O24,$A:$A,V$2) -> 1289 | W24: =SUMIFS($C:$C,$D:$D,$O24,$A:$A,W$2) -> 1925 | ... AC24: =SUMIFS($C:$C,$D:$D,$O24,$A:$A,AC$2) -> 707
A25: G6 | B25: 2579WAC31/IND | C25: 86 | D25: 46146 | E25: 1 | F25: =IF(ISNUMBER(VALUE(LEFT(B25,5)))=TRUE,LEFT(B25,5),IF(ISNUMBER(VALUE(LEFT(B25,4)))=TRUE,LEFT(B25,4),LEFT(B25,3))) -> 2579 | G25: =LEN(B25) -> 13 | H25: =VLOOKUP(B25,[1]Sheet1!$D:$AB,25,0) -> Regular-Adhe | I25: =LOOKUP(C25, $AY$3:$AY$8, $AZ$3:$AZ$8) -> 51-100 | J25: =VLOOKUP(B25,[1]Sheet1!$D:$Y,22) -> Adhe | K25: =VLOOKUP(B25,[1]Sheet1!$D:$AS,42,0) -> NORMAL | O25: 46172 | P25: =SUMIFS($C:$C,$D:$D,$O25,$A:$A,P$2) -> 939 | Q25: =SUMIFS($C:$C,$D:$D,$O25,$A:$A,Q$2) -> 1534 | R25: =SUMIFS($C:$C,$D:$D,$O25,$A:$A,R$2) -> 33 | S25: =SUMIFS($C:$C,$D:$D,$O25,$A:$A,S$2) -> 623 | T25: =SUMIFS($C:$C,$D:$D,$O25,$A:$A,T$2) -> 335 | U25: =SUMIFS($C:$C,$D:$D,$O25,$A:$A,U$2) -> 138 | V25: =SUMIFS($C:$C,$D:$D,$O25,$A:$A,V$2) -> 1041 | W25: =SUMIFS($C:$C,$D:$D,$O25,$A:$A,W$2) -> 1222 | ... AC25: =SUMIFS($C:$C,$D:$D,$O25,$A:$A,AC$2) -> 618 | AE25: Sum of Qty | AF25: Column Labels
A26: G4 | B26: 2594YAA00/IND | C26: 54 | D26: 46146 | E26: 1 | F26: =IF(ISNUMBER(VALUE(LEFT(B26,5)))=TRUE,LEFT(B26,5),IF(ISNUMBER(VALUE(LEFT(B26,4)))=TRUE,LEFT(B26,4),LEFT(B26,3))) -> 2594 | G26: =LEN(B26) -> 13 | H26: =VLOOKUP(B26,[1]Sheet1!$D:$AB,25,0) -> Regular-Adhe | I26: =LOOKUP(C26, $AY$3:$AY$8, $AZ$3:$AZ$8) -> 51-100 | J26: =VLOOKUP(B26,[1]Sheet1!$D:$Y,22) -> Adhe | K26: =VLOOKUP(B26,[1]Sheet1!$D:$AS,42,0) -> NORMAL | AE26: Row Labels | AF26: (blank) | AG26: Grand Total
A27: G5 | B27: 2598SAA30/IND | C27: 114 | D27: 46146 | E27: 2 | F27: =IF(ISNUMBER(VALUE(LEFT(B27,5)))=TRUE,LEFT(B27,5),IF(ISNUMBER(VALUE(LEFT(B27,4)))=TRUE,LEFT(B27,4),LEFT(B27,3))) -> 2598 | G27: =LEN(B27) -> 13 | H27: =VLOOKUP(B27,[1]Sheet1!$D:$AB,25,0) -> Regular-Gask | I27: =LOOKUP(C27, $AY$3:$AY$8, $AZ$3:$AZ$8) -> 101-300 | J27: =VLOOKUP(B27,[1]Sheet1!$D:$Y,22) -> Gask | K27: =VLOOKUP(B27,[1]Sheet1!$D:$AS,42,0) -> NORMAL | AE27: (blank)
A28: G5 | B28: 2598WAB00/IND | C28: 205 | D28: 46146 | E28: 1 | F28: =IF(ISNUMBER(VALUE(LEFT(B28,5)))=TRUE,LEFT(B28,5),IF(ISNUMBER(VALUE(LEFT(B28,4)))=TRUE,LEFT(B28,4),LEFT(B28,3))) -> 2598 | G28: =LEN(B28) -> 13 | H28: =VLOOKUP(B28,[1]Sheet1!$D:$AB,25,0) -> Regular-Gask | I28: =LOOKUP(C28, $AY$3:$AY$8, $AZ$3:$AZ$8) -> 101-300 | J28: =VLOOKUP(B28,[1]Sheet1!$D:$Y,22) -> Gask | K28: =VLOOKUP(B28,[1]Sheet1!$D:$AS,42,0) -> NORMAL | AE28: Grand Total
A29: G5 | B29: 2598YAB00/IND | C29: 591 | D29: 46146 | E29: 1 | F29: =IF(ISNUMBER(VALUE(LEFT(B29,5)))=TRUE,LEFT(B29,5),IF(ISNUMBER(VALUE(LEFT(B29,4)))=TRUE,LEFT(B29,4),LEFT(B29,3))) -> 2598 | G29: =LEN(B29) -> 13 | H29: =VLOOKUP(B29,[1]Sheet1!$D:$AB,25,0) -> Regular-Gask | I29: =LOOKUP(C29, $AY$3:$AY$8, $AZ$3:$AZ$8) -> 501-1000 | J29: =VLOOKUP(B29,[1]Sheet1!$D:$Y,22) -> Gask | K29: =VLOOKUP(B29,[1]Sheet1!$D:$AS,42,0) -> NORMAL
A30: G5 | B30: 2598YAB40/IND | C30: 436 | D30: 46146 | E30: 1 | F30: =IF(ISNUMBER(VALUE(LEFT(B30,5)))=TRUE,LEFT(B30,5),IF(ISNUMBER(VALUE(LEFT(B30,4)))=TRUE,LEFT(B30,4),LEFT(B30,3))) -> 2598 | G30: =LEN(B30) -> 13 | H30: =VLOOKUP(B30,[1]Sheet1!$D:$AB,25,0) -> Regular-Gask | I30: =LOOKUP(C30, $AY$3:$AY$8, $AZ$3:$AZ$8) -> 301-500 | J30: =VLOOKUP(B30,[1]Sheet1!$D:$Y,22) -> Gask | K30: =VLOOKUP(B30,[1]Sheet1!$D:$AS,42,0) -> NORMAL
A31: KMC | B31: 2603SAD31/IND | C31: 245 | D31: 46146 | E31: 2 | F31: =IF(ISNUMBER(VALUE(LEFT(B31,5)))=TRUE,LEFT(B31,5),IF(ISNUMBER(VALUE(LEFT(B31,4)))=TRUE,LEFT(B31,4),LEFT(B31,3))) -> 2603 | G31: =LEN(B31) -> 13 | H31: =VLOOKUP(B31,[1]Sheet1!$D:$AB,25,0) -> Regular-Adhe | I31: =LOOKUP(C31, $AY$3:$AY$8, $AZ$3:$AZ$8) -> 101-300 | J31: =VLOOKUP(B31,[1]Sheet1!$D:$Y,22) -> Adhe | K31: =VLOOKUP(B31,[1]Sheet1!$D:$AS,42,0) -> NORMAL
A32: G2 | B32: 2603SAD31/IND | C32: 154 | D32: 46146 | E32: 2 | F32: =IF(ISNUMBER(VALUE(LEFT(B32,5)))=TRUE,LEFT(B32,5),IF(ISNUMBER(VALUE(LEFT(B32,4)))=TRUE,LEFT(B32,4),LEFT(B32,3))) -> 2603 | G32: =LEN(B32) -> 13 | H32: =VLOOKUP(B32,[1]Sheet1!$D:$AB,25,0) -> Regular-Adhe | I32: =LOOKUP(C32, $AY$3:$AY$8, $AZ$3:$AZ$8) -> 101-300 | J32: =VLOOKUP(B32,[1]Sheet1!$D:$Y,22) -> Adhe | K32: =VLOOKUP(B32,[1]Sheet1!$D:$AS,42,0) -> NORMAL
A33: KMC | B33: 2603SAD32/IND | C33: 142 | D33: 46146 | E33: 2 | F33: =IF(ISNUMBER(VALUE(LEFT(B33,5)))=TRUE,LEFT(B33,5),IF(ISNUMBER(VALUE(LEFT(B33,4)))=TRUE,LEFT(B33,4),LEFT(B33,3))) -> 2603 | G33: =LEN(B33) -> 13 | H33: =VLOOKUP(B33,[1]Sheet1!$D:$AB,25,0) -> Regular-Adhe | I33: =LOOKUP(C33, $AY$3:$AY$8, $AZ$3:$AZ$8) -> 101-300 | J33: =VLOOKUP(B33,[1]Sheet1!$D:$Y,22) -> Adhe | K33: =VLOOKUP(B33,[1]Sheet1!$D:$AS,42,0) -> NORMAL
